Workbook

Sheet BD&LR
A1: ='Individual BD'!C118 -> 12/01/2026
A2: Block | B2: HOUR | C2: GENCO THERMAL BACKDOWN MW | D2: CGS BACKDOWN MW | E2: IPP THERMAL BACKDOWN MW | F2: WIND BACKDOWN | G2: SOLAR BACKDOWN MW | H2: LR | I2: UI | J2: Freq | K2: DAM | L2: DAM rate | M2: RTM | N2: RTM rate
A3: 1 | B3: 00:00-00:15 | C3: =SUM('Individual BD'!C3:N3)-'Individual BD'!K3-'Individual BD'!M3-'Individual BD'!N3 -> 1207.77 | D3: =IF('CGS BD CAL'!M3<20,0,'CGS BD CAL'!M3) -> 1020.3128 | E3: =SUM('Individual BD'!K3+'Individual BD'!M3+'Individual BD'!N3) -> 202.9 | F3: 0 | G3: 0 | H3: 0 | I3: ='SCADA Grid'!D4 -> 163.26 | J3: ='SCADA Grid'!C4 -> 50.04 | K3: =IEX!G11 -> 0 | L3: 2.41314 | M3: =RTM!G12 -> 761.51 | N3: 2.81057 | O3: =IF(AND(C3>1,OR($K3>100,$M3>100)),1,0) -> 1 | P3: =IF(AND(D3>1,OR($K3>100,$M3>100)),1,0) -> 1 | Q3: =IF(AND(E3>1,OR($K3>100,$M3>100)),1,0) -> 1
A4: 2 | B4: 00:15-00:30 | C4: =SUM('Individual BD'!C4:N4)-'Individual BD'!K4-'Individual BD'!M4-'Individual BD'!N4 -> 1217.43 | D4: =IF('CGS BD CAL'!M4<20,0,'CGS BD CAL'!M4) -> 1020.2728 | E4: =SUM('Individual BD'!K4+'Individual BD'!M4+'Individual BD'!N4) -> 201.3 | F4: 0 | G4: 0 | H4: 0 | I4: ='SCADA Grid'!D5 -> -3.72 | J4: ='SCADA Grid'!C5 -> 50.03 | K4: =IEX!G12 -> 0 | L4: 2.43522 | M4: =RTM!G13 -> 856.7 | N4: 2.59135 | O4: =IF(AND(C4>1,OR($K4>100,$M4>100)),1,0) -> 1 | P4: =IF(AND(D4>1,OR($K4>100,$M4>100)),1,0) -> 1 | Q4: =IF(AND(E4>1,OR($K4>100,$M4>100)),1,0) -> 1
A5: 3 | B5: 00:30-00:45 | C5: =SUM('Individual BD'!C5:N5)-'Individual BD'!K5-'Individual BD'!M5-'Individual BD'!N5 -> 1234.1 | D5: =IF('CGS BD CAL'!M5<20,0,'CGS BD CAL'!M5) -> 1020.2728 | E5: =SUM('Individual BD'!K5+'Individual BD'!M5+'Individual BD'!N5) -> 208.06 | F5: 0 | G5: 0 | H5: 0 | I5: ='SCADA Grid'!D6 -> -129.29 | J5: ='SCADA Grid'!C6 -> 50.01 | K5: =IEX!G13 -> 0 | L5: 2.469 | M5: =RTM!G14 -> 1047.08 | N5: 2.50039 | O5: =IF(AND(C5>1,OR($K5>100,$M5>100)),1,0) -> 1 | P5: =IF(AND(D5>1,OR($K5>100,$M5>100)),1,0) -> 1 | Q5: =IF(AND(E5>1,OR($K5>100,$M5>100)),1,0) -> 1
A6: 4 | B6: 00:45-01:00 | C6: =SUM('Individual BD'!C6:N6)-'Individual BD'!K6-'Individual BD'!M6-'Individual BD'!N6 -> 1241.51 | D6: =IF('CGS BD CAL'!M6<20,0,'CGS BD CAL'!M6) -> 1020.2728 | E6: =SUM('Individual BD'!K6+'Individual BD'!M6+'Individual BD'!N6) -> 206.87 | F6: 0 | G6: 0 | H6: 0 | I6: ='SCADA Grid'!D7 -> -31.77 | J6: ='SCADA Grid'!C7 -> 50.01 | K6: =IEX!G14 -> 0 | L6: 2.42933 | M6: =RTM!G15 -> 951.89 | N6: 2.49925 | O6: =IF(AND(C6>1,OR($K6>100,$M6>100)),1,0) -> 1 | P6: =IF(AND(D6>1,OR($K6>100,$M6>100)),1,0) -> 1 | Q6: =IF(AND(E6>1,OR($K6>100,$M6>100)),1,0) -> 1
A7: 5 | B7: 01:00-01:15 | C7: =SUM('Individual BD'!C7:N7)-'Individual BD'!K7-'Individual BD'!M7-'Individual BD'!N7 -> 1247.56 | D7: =IF('CGS BD CAL'!M7<20,0,'CGS BD CAL'!M7) -> 1020.2728 | E7: =SUM('Individual BD'!K7+'Individual BD'!M7+'Individual BD'!N7) -> 202.06 | F7: 0 | G7: 0 | H7: 0 | I7: ='SCADA Grid'!D8 -> -130.85 | J7: ='SCADA Grid'!C8 -> 50.01 | K7: =IEX!G15 -> 0 | L7: 2.41618 | M7: =RTM!G16 -> 856.68 | N7: 2.04901 | O7: =IF(AND(C7>1,OR($K7>100,$M7>100)),1,0) -> 1 | P7: =IF(AND(D7>1,OR($K7>100,$M7>100)),1,0) -> 1 | Q7: =IF(AND(E7>1,OR($K7>100,$M7>100)),1,0) -> 1
A8: 6 | B8: 01:15-01:30 | C8: =SUM('Individual BD'!C8:N8)-'Individual BD'!K8-'Individual BD'!M8-'Individual BD'!N8 -> 1252.21 | D8: =IF('CGS BD CAL'!M8<20,0,'CGS BD CAL'!M8) -> 1020.2728 | E8: =SUM('Individual BD'!K8+'Individual BD'!M8+'Individual BD'!N8) -> 251.62 | F8: 0 | G8: 0 | H8: 0 | I8: ='SCADA Grid'!D9 -> -27.25 | J8: ='SCADA Grid'!C9 -> 50.01 | K8: =IEX!G16 -> 0 | L8: 2.41602 | M8: =RTM!G17 -> 761.48 | N8: 1.90879 | O8: =IF(AND(C8>1,OR($K8>100,$M8>100)),1,0) -> 1 | P8: =IF(AND(D8>1,OR($K8>100,$M8>100)),1,0) -> 1 | Q8: =IF(AND(E8>1,OR($K8>100,$M8>100)),1,0) -> 1
A9: 7 | B9: 01:30-01:45 | C9: =SUM('Individual BD'!C9:N9)-'Individual BD'!K9-'Individual BD'!M9-'Individual BD'!N9 -> 1506.33 | D9: =IF('CGS BD CAL'!M9<20,0,'CGS BD CAL'!M9) -> 1129.7021 | E9: =SUM('Individual BD'!K9+'Individual BD'!M9+'Individual BD'!N9) -> 305.79 | F9: 0 | G9: 0 | H9: 0 | I9: ='SCADA Grid'!D10 -> -10.79 | J9: ='SCADA Grid'!C10 -> 50.02 | K9: =IEX!G17 -> 0 | L9: 2.38046 | M9: =RTM!G18 -> 856.68 | N9: 2.01963 | O9: =IF(AND(C9>1,OR($K9>100,$M9>100)),1,0) -> 1 | P9: =IF(AND(D9>1,OR($K9>100,$M9>100)),1,0) -> 1 | Q9: =IF(AND(E9>1,OR($K9>100,$M9>100)),1,0) -> 1
A10: 8 | B10: 01:45-02:00 | C10: =SUM('Individual BD'!C10:N10)-'Individual BD'!K10-'Individual BD'!M10-'Individual BD'!N10 -> 1518.03 | D10: =IF('CGS BD CAL'!M10<20,0,'CGS BD CAL'!M10) -> 1144.1221 | E10: =SUM('Individual BD'!K10+'Individual BD'!M10+'Individual BD'!N10) -> 353.51 | F10: 0 | G10: 0 | H10: 0 | I10: ='SCADA Grid'!D11 -> 66.22 | J10: ='SCADA Grid'!C11 -> 50.03 | K10: =IEX!G18 -> 0 | L10: 2.38047 | M10: =RTM!G19 -> 856.67 | N10: 1.91042 | O10: =IF(AND(C10>1,OR($K10>100,$M10>100)),1,0) -> 1 | P10: =IF(AND(D10>1,OR($K10>100,$M10>100)),1,0) -> 1 | Q10: =IF(AND(E10>1,OR($K10>100,$M10>100)),1,0) -> 1
A11: 9 | B11: 02:00-02:15 | C11: =SUM('Individual BD'!C11:N11)-'Individual BD'!K11-'Individual BD'!M11-'Individual BD'!N11 -> 1508.9 | D11: =IF('CGS BD CAL'!M11<20,0,'CGS BD CAL'!M11) -> 1144.1221 | E11: =SUM('Individual BD'!K11+'Individual BD'!M11+'Individual BD'!N11) -> 364.37 | F11: 0 | G11: 0 | H11: 0 | I11: ='SCADA Grid'!D12 -> -79.6 | J11: ='SCADA Grid'!C12 -> 50.02 | K11: =IEX!G19 -> 0 | L11: 2.41619 | M11: =RTM!G20 -> 951.86 | N11: 1.90862 | O11: =IF(AND(C11>1,OR($K11>100,$M11>100)),1,0) -> 1 | P11: =IF(AND(D11>1,OR($K11>100,$M11>100)),1,0) -> 1 | Q11: =IF(AND(E11>1,OR($K11>100,$M11>100)),1,0) -> 1
A12: 10 | B12: 02:15-02:30 | C12: =SUM('Individual BD'!C12:N12)-'Individual BD'!K12-'Individual BD'!M12-'Individual BD'!N12 -> 1504.89 | D12: =IF('CGS BD CAL'!M12<20,0,'CGS BD CAL'!M12) -> 1144.1221 | E12: =SUM('Individual BD'!K12+'Individual BD'!M12+'Individual BD'!N12) -> 361.45 | F12: 0 | G12: 0 | H12: 0 | I12: ='SCADA Grid'!D13 -> -33.92 | J12: ='SCADA Grid'!C13 -> 49.99 | K12: =IEX!G20 -> 0 | L12: 2.41656 | M12: =RTM!G21 -> 951.86 | N12: 1.9083 | O12: =IF(AND(C12>1,OR($K12>100,$M12>100)),1,0) -> 1 | P12: =IF(AND(D12>1,OR($K12>100,$M12>100)),1,0) -> 1 | Q12: =IF(AND(E12>1,OR($K12>100,$M12>100)),1,0) -> 1
A13: 11 | B13: 02:30-02:45 | C13: =SUM('Individual BD'!C13:N13)-'Individual BD'!K13-'Individual BD'!M13-'Individual BD'!N13 -> 1495.11 | D13: =IF('CGS BD CAL'!M13<20,0,'CGS BD CAL'!M13) -> 1144.1221 | E13: =SUM('Individual BD'!K13+'Individual BD'!M13+'Individual BD'!N13) -> 361.87 | F13: 0 | G13: 0 | H13: 0 | I13: ='SCADA Grid'!D14 -> 24.62 | J13: ='SCADA Grid'!C14 -> 50 | K13: =IEX!G21 -> 0 | L13: 2.42055 | M13: =RTM!G22 -> 951.86 | N13: 1.90819 | O13: =IF(AND(C13>1,OR($K13>100,$M13>100)),1,0) -> 1 | P13: =IF(AND(D13>1,OR($K13>100,$M13>100)),1,0) -> 1 | Q13: =IF(AND(E13>1,OR($K13>100,$M13>100)),1,0) -> 1
A14: 12 | B14: 02:45-03:00 | C14: =SUM('Individual BD'!C14:N14)-'Individual BD'!K14-'Individual BD'!M14-'Individual BD'!N14 -> 1498.81 | D14: =IF('CGS BD CAL'!M14<20,0,'CGS BD CAL'!M14) -> 1144.1221 | E14: =SUM('Individual BD'!K14+'Individual BD'!M14+'Individual BD'!N14) -> 361.77 | F14: 0 | G14: 0 | H14: 0 | I14: ='SCADA Grid'!D15 -> 39.24 | J14: ='SCADA Grid'!C15 -> 49.98 | K14: =IEX!G22 -> 0 | L14: 2.4209 | M14: =RTM!G23 -> 951.85 | N14: 1.89933 | O14: =IF(AND(C14>1,OR($K14>100,$M14>100)),1,0) -> 1 | P14: =IF(AND(D14>1,OR($K14>100,$M14>100)),1,0) -> 1 | Q14: =IF(AND(E14>1,OR($K14>100,$M14>100)),1,0) -> 1
... A98: 96 | B98: 23:45-24:00 | C98: =SUM('Individual BD'!C98:N98)-'Individual BD'!K98-'Individual BD'!M98-'Individual BD'!N98 -> 1057.09 | D98: =IF('CGS BD CAL'!M98<20,0,'CGS BD CAL'!M98) -> 1032.4365 | E98: =SUM('Individual BD'!K98+'Individual BD'!M98+'Individual BD'!N98) -> 205.93 | F98: 0 | G98: 0 | H98: 0 | I98: ='SCADA Grid'!D99 -> -170.41 | J98: ='SCADA Grid'!C99 -> 50.03 | K98: =IEX!G106 -> 0 | L98: 2.83968 | M98: =RTM!G107 -> 571.1 | N98: 2.85274 | O98: =IF(AND(C98>1,OR($K98>100,$M98>100)),1,0) -> 1 | P98: =IF(AND(D98>1,OR($K98>100,$M98>100)),1,0) -> 1 | Q98: =IF(AND(E98>1,OR($K98>100,$M98>100)),1,0) -> 1
B99: IN MU (Net) | C99: =AVERAGE(C3:C98)*24/1000 -> 14.70867 | D99: =AVERAGE(D3:D98)*24/1000 -> 9.0232677 | E99: =AVERAGE(E3:E98)*24/1000 -> 1.6308325 | F99: =AVERAGE(F3:F98)*24/1000 -> 0 | G99: =AVERAGE(G3:G98)*24/1000 -> 0 | H99: =AVERAGE(H3:H98)*24/1000 -> 0 | I99: =AVERAGE(I3:I98)*24/1000 -> -1.856135 | J99: =AVERAGE(J3:J98) -> 49.981667 | K99: =AVERAGE(K3:K98)*24/1000 -> 5.6373225 | M99: =AVERAGE(M3:M98)*24/1000 -> 8.500805
B100: Highlighted fields indicates State Thermal backdown with DAM/RTM purchases : TB Nos. 1-32, 51-63 & 93-96: MBED with RTM purchases. TB Nos. 39 to 43 : Due to Rise in Solar and wind generations.
B101: Highlighted fields indicates CGS Thermal backdown with DAM/RTM purchases:
B102: Highlighted fields indicates IPP Thermal backdown with DAM/RTM purchases:
B106: Minimum | C106: =MIN(C3:C98) -> 0 | D106: =MIN(D3:D98) -> 0 | E106: =MIN(E3:E98) -> 0 | F106: =MIN(F3:F98) -> 0 | G106: =MIN(G3:G98) -> 0 | I106: =MIN(I3:I98) -> -647.5 | J106: =MIN(J3:J98) -> 45.96 | K106: =MIN(K3:K98) -> -400 | M106: =MIN(M3:M98) -> -600 | N106: =MIN(N3:N98) -> 1.89933
B107: Maximum | C107: =MAX(C3:C98) -> 1518.03 | D107: =MAX(D3:D98) -> 1146.0621 | E107: =MAX(E3:E98) -> 364.37 | F107: =MAX(F3:F98) -> 0 | G107: =MAX(G3:G98) -> 0 | I107: =MAX(I3:I98) -> 413.68 | J107: =MAX(J3:J98) -> 50.25 | K107: =MAX(K3:K98) -> 1618.23 | M107: =MAX(M3:M98) -> 1142.28 | N107: =MAX(N3:N98) -> 10
K109: =MIN(K3:K98) -> -400
B122: 0

Sheet Individual BD
A1: ='BD&LR'!A1:F1 -> 12/01/2026
A2: Block | B2: HOUR | C2: RTPP Stg - I | D2: RTPP Stg - II | E2: RTPP Stg - III | F2: VTS (1-6) | G2: RTPP Stg - IV | H2: VTPS - IV | I2: K'Patnam Stg - I | J2: K'Patnam Stg - II | K2: Hinduja | L2: VTPS - V | M2: SEIL-125 MW | N2: SEIL-502 MW | P2: Difference b/w DCs and Actual
A3: 1 | B3: 00:00-00:15 | C3: =IF('BD Start'!C3=0,0,IF('BD Start'!C3-(-SUM(Actual!$I3:$J3))<0,0,'BD Start'!C3-(-SUM(Actual!$I3:$J3)))) -> 26.27 | D3: =IF('BD Start'!D3=0,0,IF('BD Start'!D3-(-SUM(Actual!$K3:$L3))<0,0,'BD Start'!D3-(-SUM(Actual!$K3:$L3)))) -> 170.79 | E3: =IF('BD Start'!E3=0,0,IF('BD Start'!E3-(-Actual!$M3)<0,0,'BD Start'!E3-(-Actual!$M3))) -> 70.75 | F3: =IF('BD Start'!F3=0,0,IF('BD Start'!F3-(-SUM(Actual!$B3:$G3))<0,0,'BD Start'!F3-(-SUM(Actual!$B3:$G3)))) -> 13.77 | G3: =IF('BD Start'!G3=0,0,IF('BD Start'!G3-(-Actual!$N3)<0,0,'BD Start'!G3-(-Actual!$N3))) -> 126.16 | H3: =IF('BD Start'!H3=0,0,IF('BD Start'!H3-(-Actual!$H3)<0,0,'BD Start'!H3-(-Actual!$H3))) -> 196.31 | I3: =IF('BD Start'!I3=0,0,IF('BD Start'!I3-(-SUM(Actual!$O3:$P3))<0,0,'BD Start'!I3-(-SUM(Actual!$O3:$P3)))) -> 603.72 | J3: =IF('BD Start'!J3=0,0,IF('BD Start'!J3-(-Actual!$AA3)<0,0,'BD Start'!J3-(-Actual!$AA3))) -> 0 | K3: =IF('BD Start'!K3=0,0,IF('BD Start'!K3-('DATA-CMD'!D3)<0,0,'BD Start'!K3-('DATA-CMD'!D3))) -> 202.9 | L3: =IF('BD Start'!L3=0,0,IF('BD Start'!L3-(Actual!$AB3)<0,0,'BD Start'!L3-(Actual!$AB3))) -> 0 | M3: =IF('BD Start'!M3>0,IF(('BD Start'!M3-'DATA-CMD'!L3+TPCIL!O13)>=125,125,IF(('BD Start'!M3-'DATA-CMD'!L3+TPCIL!O13)<0,0,('BD Start'!M3-'DATA-CMD'!L3+TPCIL!O13))),0) -> 0 | N3: =IF('BD Start'!N3=0,0,IF('BD Start'!N3-O3<0,0,'BD Start'!N3-O3)) -> 0 | O3: ='DATA-CMD'!L3+TPCIL!E13+TPCIL!F13+TPCIL!G13+TPCIL!H13 -> 459.09 | P3: ='BD Start'!P3+'BD Start'!Q3-'DATA-CMD'!M3 -> 0
A4: 2 | B4: 00:15-00:30 | C4: =IF('BD Start'!C4=0,0,IF('BD Start'!C4-(-SUM(Actual!$I4:$J4))<0,0,'BD Start'!C4-(-SUM(Actual!$I4:$J4)))) -> 27.21 | D4: =IF('BD Start'!D4=0,0,IF('BD Start'!D4-(-SUM(Actual!$K4:$L4))<0,0,'BD Start'!D4-(-SUM(Actual!$K4:$L4)))) -> 171.95 | E4: =IF('BD Start'!E4=0,0,IF('BD Start'!E4-(-Actual!$M4)<0,0,'BD Start'!E4-(-Actual!$M4))) -> 68.86 | F4: =IF('BD Start'!F4=0,0,IF('BD Start'!F4-(-SUM(Actual!$B4:$G4))<0,0,'BD Start'!F4-(-SUM(Actual!$B4:$G4)))) -> 13.42 | G4: =IF('BD Start'!G4=0,0,IF('BD Start'!G4-(-Actual!$N4)<0,0,'BD Start'!G4-(-Actual!$N4))) -> 130.63 | H4: =IF('BD Start'!H4=0,0,IF('BD Start'!H4-(-Actual!$H4)<0,0,'BD Start'!H4-(-Actual!$H4))) -> 195.49 | I4: =IF('BD Start'!I4=0,0,IF('BD Start'!I4-(-SUM(Actual!$O4:$P4))<0,0,'BD Start'!I4-(-SUM(Actual!$O4:$P4)))) -> 609.87 | J4: =IF('BD Start'!J4=0,0,IF('BD Start'!J4-(-Actual!$AA4)<0,0,'BD Start'!J4-(-Actual!$AA4))) -> 0 | K4: =IF('BD Start'!K4=0,0,IF('BD Start'!K4-('DATA-CMD'!D4)<0,0,'BD Start'!K4-('DATA-CMD'!D4))) -> 201.3 | L4: =IF('BD Start'!L4=0,0,IF('BD Start'!L4-(Actual!$AB4)<0,0,'BD Start'!L4-(Actual!$AB4))) -> 0 | M4: =IF('BD Start'!M4>0,IF(('BD Start'!M4-'DATA-CMD'!L4+TPCIL!O14)>=125,125,IF(('BD Start'!M4-'DATA-CMD'!L4+TPCIL!O14)<0,0,('BD Start'!M4-'DATA-CMD'!L4+TPCIL!O14))),0) -> 0 | N4: =IF('BD Start'!N4=0,0,IF('BD Start'!N4-O4<0,0,'BD Start'!N4-O4)) -> 0 | O4: ='DATA-CMD'!L4+TPCIL!E14+TPCIL!F14+TPCIL!G14+TPCIL!H14 -> 501.27 | P4: ='BD Start'!P4+'BD Start'!Q4-'DATA-CMD'!M4 -> 0
A5: 3 | B5: 00:30-00:45 | C5: =IF('BD Start'!C5=0,0,IF('BD Start'!C5-(-SUM(Actual!$I5:$J5))<0,0,'BD Start'!C5-(-SUM(Actual!$I5:$J5)))) -> 35.5 | D5: =IF('BD Start'!D5=0,0,IF('BD Start'!D5-(-SUM(Actual!$K5:$L5))<0,0,'BD Start'!D5-(-SUM(Actual!$K5:$L5)))) -> 173.44 | E5: =IF('BD Start'!E5=0,0,IF('BD Start'!E5-(-Actual!$M5)<0,0,'BD Start'!E5-(-Actual!$M5))) -> 71.86 | F5: =IF('BD Start'!F5=0,0,IF('BD Start'!F5-(-SUM(Actual!$B5:$G5))<0,0,'BD Start'!F5-(-SUM(Actual!$B5:$G5)))) -> 16.55 | G5: =IF('BD Start'!G5=0,0,IF('BD Start'!G5-(-Actual!$N5)<0,0,'BD Start'!G5-(-Actual!$N5))) -> 131.23 | H5: =IF('BD Start'!H5=0,0,IF('BD Start'!H5-(-Actual!$H5)<0,0,'BD Start'!H5-(-Actual!$H5))) -> 194.96 | I5: =IF('BD Start'!I5=0,0,IF('BD Start'!I5-(-SUM(Actual!$O5:$P5))<0,0,'BD Start'!I5-(-SUM(Actual!$O5:$P5)))) -> 610.56 | J5: =IF('BD Start'!J5=0,0,IF('BD Start'!J5-(-Actual!$AA5)<0,0,'BD Start'!J5-(-Actual!$AA5))) -> 0 | K5: =IF('BD Start'!K5=0,0,IF('BD Start'!K5-('DATA-CMD'!D5)<0,0,'BD Start'!K5-('DATA-CMD'!D5))) -> 208.06 | L5: =IF('BD Start'!L5=0,0,IF('BD Start'!L5-(Actual!$AB5)<0,0,'BD Start'!L5-(Actual!$AB5))) -> 0 | M5: =IF('BD Start'!M5>0,IF(('BD Start'!M5-'DATA-CMD'!L5+TPCIL!O15)>=125,125,IF(('BD Start'!M5-'DATA-CMD'!L5+TPCIL!O15)<0,0,('BD Start'!M5-'DATA-CMD'!L5+TPCIL!O15))),0) -> 0 | N5: =IF('BD Start'!N5=0,0,IF('BD Start'!N5-O5<0,0,'BD Start'!N5-O5)) -> 0 | O5: ='DATA-CMD'!L5+TPCIL!E15+TPCIL!F15+TPCIL!G15+TPCIL!H15 -> 502.21 | P5: ='BD Start'!P5+'BD Start'!Q5-'DATA-CMD'!M5 -> 0
A6: 4 | B6: 00:45-01:00 | C6: =IF('BD Start'!C6=0,0,IF('BD Start'!C6-(-SUM(Actual!$I6:$J6))<0,0,'BD Start'!C6-(-SUM(Actual!$I6:$J6)))) -> 43.49 | D6: =IF('BD Start'!D6=0,0,IF('BD Start'!D6-(-SUM(Actual!$K6:$L6))<0,0,'BD Start'!D6-(-SUM(Actual!$K6:$L6)))) -> 172 | E6: =IF('BD Start'!E6=0,0,IF('BD Start'!E6-(-Actual!$M6)<0,0,'BD Start'!E6-(-Actual!$M6))) -> 69.12 | F6: =IF('BD Start'!F6=0,0,IF('BD Start'!F6-(-SUM(Actual!$B6:$G6))<0,0,'BD Start'!F6-(-SUM(Actual!$B6:$G6)))) -> 20.07 | G6: =IF('BD Start'!G6=0,0,IF('BD Start'!G6-(-Actual!$N6)<0,0,'BD Start'!G6-(-Actual!$N6))) -> 131.23 | H6: =IF('BD Start'!H6=0,0,IF('BD Start'!H6-(-Actual!$H6)<0,0,'BD Start'!H6-(-Actual!$H6))) -> 195.87 | I6: =IF('BD Start'!I6=0,0,IF('BD Start'!I6-(-SUM(Actual!$O6:$P6))<0,0,'BD Start'!I6-(-SUM(Actual!$O6:$P6)))) -> 609.73 | J6: =IF('BD Start'!J6=0,0,IF('BD Start'!J6-(-Actual!$AA6)<0,0,'BD Start'!J6-(-Actual!$AA6))) -> 0 | K6: =IF('BD Start'!K6=0,0,IF('BD Start'!K6-('DATA-CMD'!D6)<0,0,'BD Start'!K6-('DATA-CMD'!D6))) -> 206.87 | L6: =IF('BD Start'!L6=0,0,IF('BD Start'!L6-(Actual!$AB6)<0,0,'BD Start'!L6-(Actual!$AB6))) -> 0 | M6: =IF('BD Start'!M6>0,IF(('BD Start'!M6-'DATA-CMD'!L6+TPCIL!O16)>=125,125,IF(('BD Start'!M6-'DATA-CMD'!L6+TPCIL!O16)<0,0,('BD Start'!M6-'DATA-CMD'!L6+TPCIL!O16))),0) -> 0 | N6: =IF('BD Start'!N6=0,0,IF('BD Start'!N6-O6<0,0,'BD Start'!N6-O6)) -> 0 | O6: ='DATA-CMD'!L6+TPCIL!E16+TPCIL!F16+TPCIL!G16+TPCIL!H16 -> 502.44 | P6: ='BD Start'!P6+'BD Start'!Q6-'DATA-CMD'!M6 -> 0
A7: 5 | B7: 01:00-01:15 | C7: =IF('BD Start'!C7=0,0,IF('BD Start'!C7-(-SUM(Actual!$I7:$J7))<0,0,'BD Start'!C7-(-SUM(Actual!$I7:$J7)))) -> 46.45 | D7: =IF('BD Start'!D7=0,0,IF('BD Start'!D7-(-SUM(Actual!$K7:$L7))<0,0,'BD Start'!D7-(-SUM(Actual!$K7:$L7)))) -> 172.85 | E7: =IF('BD Start'!E7=0,0,IF('BD Start'!E7-(-Actual!$M7)<0,0,'BD Start'!E7-(-Actual!$M7))) -> 69.68 | F7: =IF('BD Start'!F7=0,0,IF('BD Start'!F7-(-SUM(Actual!$B7:$G7))<0,0,'BD Start'!F7-(-SUM(Actual!$B7:$G7)))) -> 26.07 | G7: =IF('BD Start'!G7=0,0,IF('BD Start'!G7-(-Actual!$N7)<0,0,'BD Start'!G7-(-Actual!$N7))) -> 133.35 | H7: =IF('BD Start'!H7=0,0,IF('BD Start'!H7-(-Actual!$H7)<0,0,'BD Start'!H7-(-Actual!$H7))) -> 197 | I7: =IF('BD Start'!I7=0,0,IF('BD Start'!I7-(-SUM(Actual!$O7:$P7))<0,0,'BD Start'!I7-(-SUM(Actual!$O7:$P7)))) -> 602.16 | J7: =IF('BD Start'!J7=0,0,IF('BD Start'!J7-(-Actual!$AA7)<0,0,'BD Start'!J7-(-Actual!$AA7))) -> 0 | K7: =IF('BD Start'!K7=0,0,IF('BD Start'!K7-('DATA-CMD'!D7)<0,0,'BD Start'!K7-('DATA-CMD'!D7))) -> 202.06 | L7: =IF('BD Start'!L7=0,0,IF('BD Start'!L7-(Actual!$AB7)<0,0,'BD Start'!L7-(Actual!$AB7))) -> 0 | M7: =IF('BD Start'!M7>0,IF(('BD Start'!M7-'DATA-CMD'!L7+TPCIL!O17)>=125,125,IF(('BD Start'!M7-'DATA-CMD'!L7+TPCIL!O17)<0,0,('BD Start'!M7-'DATA-CMD'!L7+TPCIL!O17))),0) -> 0 | N7: =IF('BD Start'!N7=0,0,IF('BD Start'!N7-O7<0,0,'BD Start'!N7-O7)) -> 0 | O7: ='DATA-CMD'!L7+TPCIL!E17+TPCIL!F17+TPCIL!G17+TPCIL!H17 -> 488.97 | P7: ='BD Start'!P7+'BD Start'!Q7-'DATA-CMD'!M7 -> 0
A8: 6 | B8: 01:15-01:30 | C8: =IF('BD Start'!C8=0,0,IF('BD Start'!C8-(-SUM(Actual!$I8:$J8))<0,0,'BD Start'!C8-(-SUM(Actual!$I8:$J8)))) -> 50.78 | D8: =IF('BD Start'!D8=0,0,IF('BD Start'!D8-(-SUM(Actual!$K8:$L8))<0,0,'BD Start'!D8-(-SUM(Actual!$K8:$L8)))) -> 174.39 | E8: =IF('BD Start'!E8=0,0,IF('BD Start'!E8-(-Actual!$M8)<0,0,'BD Start'!E8-(-Actual!$M8))) -> 71.19 | F8: =IF('BD Start'!F8=0,0,IF('BD Start'!F8-(-SUM(Actual!$B8:$G8))<0,0,'BD Start'!F8-(-SUM(Actual!$B8:$G8)))) -> 22.35 | G8: =IF('BD Start'!G8=0,0,IF('BD Start'!G8-(-Actual!$N8)<0,0,'BD Start'!G8-(-Actual!$N8))) -> 136.32 | H8: =IF('BD Start'!H8=0,0,IF('BD Start'!H8-(-Actual!$H8)<0,0,'BD Start'!H8-(-Actual!$H8))) -> 193.95 | I8: =IF('BD Start'!I8=0,0,IF('BD Start'!I8-(-SUM(Actual!$O8:$P8))<0,0,'BD Start'!I8-(-SUM(Actual!$O8:$P8)))) -> 603.23 | J8: =IF('BD Start'!J8=0,0,IF('BD Start'!J8-(-Actual!$AA8)<0,0,'BD Start'!J8-(-Actual!$AA8))) -> 0 | K8: =IF('BD Start'!K8=0,0,IF('BD Start'!K8-('DATA-CMD'!D8)<0,0,'BD Start'!K8-('DATA-CMD'!D8))) -> 203.98 | L8: =IF('BD Start'!L8=0,0,IF('BD Start'!L8-(Actual!$AB8)<0,0,'BD Start'!L8-(Actual!$AB8))) -> 0 | M8: =IF('BD Start'!M8>0,IF(('BD Start'!M8-'DATA-CMD'!L8+TPCIL!O18)>=125,125,IF(('BD Start'!M8-'DATA-CMD'!L8+TPCIL!O18)<0,0,('BD Start'!M8-'DATA-CMD'!L8+TPCIL!O18))),0) -> 0 | N8: =IF('BD Start'!N8=0,0,IF('BD Start'!N8-O8<0,0,'BD Start'!N8-O8)) -> 47.64 | O8: ='DATA-CMD'!L8+TPCIL!E18+TPCIL!F18+TPCIL!G18+TPCIL!H18 -> 454.36 | P8: ='BD Start'!P8+'BD Start'!Q8-'DATA-CMD'!M8 -> 0
A9: 7 | B9: 01:30-01:45 | C9: =IF('BD Start'!C9=0,0,IF('BD Start'!C9-(-SUM(Actual!$I9:$J9))<0,0,'BD Start'!C9-(-SUM(Actual!$I9:$J9)))) -> 51.5 | D9: =IF('BD Start'!D9=0,0,IF('BD Start'!D9-(-SUM(Actual!$K9:$L9))<0,0,'BD Start'!D9-(-SUM(Actual!$K9:$L9)))) -> 172.76 | E9: =IF('BD Start'!E9=0,0,IF('BD Start'!E9-(-Actual!$M9)<0,0,'BD Start'!E9-(-Actual!$M9))) -> 69.97 | F9: =IF('BD Start'!F9=0,0,IF('BD Start'!F9-(-SUM(Actual!$B9:$G9))<0,0,'BD Start'!F9-(-SUM(Actual!$B9:$G9)))) -> 22.15 | G9: =IF('BD Start'!G9=0,0,IF('BD Start'!G9-(-Actual!$N9)<0,0,'BD Start'!G9-(-Actual!$N9))) -> 136.32 | H9: =IF('BD Start'!H9=0,0,IF('BD Start'!H9-(-Actual!$H9)<0,0,'BD Start'!H9-(-Actual!$H9))) -> 194.41 | I9: =IF('BD Start'!I9=0,0,IF('BD Start'!I9-(-SUM(Actual!$O9:$P9))<0,0,'BD Start'!I9-(-SUM(Actual!$O9:$P9)))) -> 590.88 | J9: =IF('BD Start'!J9=0,0,IF('BD Start'!J9-(-Actual!$AA9)<0,0,'BD Start'!J9-(-Actual!$AA9))) -> 0 | K9: =IF('BD Start'!K9=0,0,IF('BD Start'!K9-('DATA-CMD'!D9)<0,0,'BD Start'!K9-('DATA-CMD'!D9))) -> 202.46 | L9: =IF('BD Start'!L9=0,0,IF('BD Start'!L9-(Actual!$AB9)<0,0,'BD Start'!L9-(Actual!$AB9))) -> 268.34 | M9: =IF('BD Start'!M9>0,IF(('BD Start'!M9-'DATA-CMD'!L9+TPCIL!O19)>=125,125,IF(('BD Start'!M9-'DATA-CMD'!L9+TPCIL!O19)<0,0,('BD Start'!M9-'DATA-CMD'!L9+TPCIL!O19))),0) -> 0 | N9: =IF('BD Start'!N9=0,0,IF('BD Start'!N9-O9<0,0,'BD Start'!N9-O9)) -> 103.33 | O9: ='DATA-CMD'!L9+TPCIL!E19+TPCIL!F19+TPCIL!G19+TPCIL!H19 -> 398.67 | P9: ='BD Start'!P9+'BD Start'!Q9-'DATA-CMD'!M9 -> 0
A10: 8 | B10: 01:45-02:00 | C10: =IF('BD Start'!C10=0,0,IF('BD Start'!C10-(-SUM(Actual!$I10:$J10))<0,0,'BD Start'!C10-(-SUM(Actual!$I10:$J10)))) -> 56.24 | D10: =IF('BD Start'!D10=0,0,IF('BD Start'!D10-(-SUM(Actual!$K10:$L10))<0,0,'BD Start'!D10-(-SUM(Actual!$K10:$L10)))) -> 172.94 | E10: =IF('BD Start'!E10=0,0,IF('BD Start'!E10-(-Actual!$M10)<0,0,'BD Start'!E10-(-Actual!$M10))) -> 69.37 | F10: =IF('BD Start'!F10=0,0,IF('BD Start'!F10-(-SUM(Actual!$B10:$G10))<0,0,'BD Start'!F10-(-SUM(Actual!$B10:$G10)))) -> 18.04 | G10: =IF('BD Start'!G10=0,0,IF('BD Start'!G10-(-Actual!$N10)<0,0,'BD Start'!G10-(-Actual!$N10))) -> 132.35 | H10: =IF('BD Start'!H10=0,0,IF('BD Start'!H10-(-Actual!$H10)<0,0,'BD Start'!H10-(-Actual!$H10))) -> 200.88 | I10: =IF('BD Start'!I10=0,0,IF('BD Start'!I10-(-SUM(Actual!$O10:$P10))<0,0,'BD Start'!I10-(-SUM(Actual!$O10:$P10)))) -> 601 | J10: =IF('BD Start'!J10=0,0,IF('BD Start'!J10-(-Actual!$AA10)<0,0,'BD Start'!J10-(-Actual!$AA10))) -> 0 | K10: =IF('BD Start'!K10=0,0,IF('BD Start'!K10-('DATA-CMD'!D10)<0,0,'BD Start'!K10-('DATA-CMD'!D10))) -> 204.23 | L10: =IF('BD Start'!L10=0,0,IF('BD Start'!L10-(Actual!$AB10)<0,0,'BD Start'!L10-(Actual!$AB10))) -> 267.21 | M10: =IF('BD Start'!M10>0,IF(('BD Start'!M10-'DATA-CMD'!L10+TPCIL!O20)>=125,125,IF(('BD Start'!M10-'DATA-CMD'!L10+TPCIL!O20)<0,0,('BD Start'!M10-'DATA-CMD'!L10+TPCIL!O20))),0) -> 0 | N10: =IF('BD Start'!N10=0,0,IF('BD Start'!N10-O10<0,0,'BD Start'!N10-O10)) -> 149.28 | O10: ='DATA-CMD'!L10+TPCIL!E20+TPCIL!F20+TPCIL!G20+TPCIL!H20 -> 352.72 | P10: ='BD Start'!P10+'BD Start'!Q10-'DATA-CMD'!M10 -> 0
A11: 9 | B11: 02:00-02:15 | C11: =IF('BD Start'!C11=0,0,IF('BD Start'!C11-(-SUM(Actual!$I11:$J11))<0,0,'BD Start'!C11-(-SUM(Actual!$I11:$J11)))) -> 52.4 | D11: =IF('BD Start'!D11=0,0,IF('BD Start'!D11-(-SUM(Actual!$K11:$L11))<0,0,'BD Start'!D11-(-SUM(Actual!$K11:$L11)))) -> 170.93 | E11: =IF('BD Start'!E11=0,0,IF('BD Start'!E11-(-Actual!$M11)<0,0,'BD Start'!E11-(-Actual!$M11))) -> 69.96 | F11: =IF('BD Start'!F11=0,0,IF('BD Start'!F11-(-SUM(Actual!$B11:$G11))<0,0,'BD Start'!F11-(-SUM(Actual!$B11:$G11)))) -> 11.18 | G11: =IF('BD Start'!G11=0,0,IF('BD Start'!G11-(-Actual!$N11)<0,0,'BD Start'!G11-(-Actual!$N11))) -> 127.79 | H11: =IF('BD Start'!H11=0,0,IF('BD Start'!H11-(-Actual!$H11)<0,0,'BD Start'!H11-(-Actual!$H11))) -> 195.24 | I11: =IF('BD Start'!I11=0,0,IF('BD Start'!I11-(-SUM(Actual!$O11:$P11))<0,0,'BD Start'!I11-(-SUM(Actual!$O11:$P11)))) -> 621.88 | J11: =IF('BD Start'!J11=0,0,IF('BD Start'!J11-(-Actual!$AA11)<0,0,'BD Start'!J11-(-Actual!$AA11))) -> 0 | K11: =IF('BD Start'!K11=0,0,IF('BD Start'!K11-('DATA-CMD'!D11)<0,0,'BD Start'!K11-('DATA-CMD'!D11))) -> 206.89 | L11: =IF('BD Start'!L11=0,0,IF('BD Start'!L11-(Actual!$AB11)<0,0,'BD Start'!L11-(Actual!$AB11))) -> 259.52 | M11: =IF('BD Start'!M11>0,IF(('BD Start'!M11-'DATA-CMD'!L11+TPCIL!O21)>=125,125,IF(('BD Start'!M11-'DATA-CMD'!L11+TPCIL!O21)<0,0,('BD Start'!M11-'DATA-CMD'!L11+TPCIL!O21))),0) -> 0 | N11: =IF('BD Start'!N11=0,0,IF('BD Start'!N11-O11<0,0,'BD Start'!N11-O11)) -> 157.48 | O11: ='DATA-CMD'!L11+TPCIL!E21+TPCIL!F21+TPCIL!G21+TPCIL!H21 -> 344.52 | P11: ='BD Start'!P11+'BD Start'!Q11-'DATA-CMD'!M11 -> 0
A12: 10 | B12: 02:15-02:30 | C12: =IF('BD Start'!C12=0,0,IF('BD Start'!C12-(-SUM(Actual!$I12:$J12))<0,0,'BD Start'!C12-(-SUM(Actual!$I12:$J12)))) -> 52.91 | D12: =IF('BD Start'!D12=0,0,IF('BD Start'!D12-(-SUM(Actual!$K12:$L12))<0,0,'BD Start'!D12-(-SUM(Actual!$K12:$L12)))) -> 174 | E12: =IF('BD Start'!E12=0,0,IF('BD Start'!E12-(-Actual!$M12)<0,0,'BD Start'!E12-(-Actual!$M12))) -> 68.9 | F12: =IF('BD Start'!F12=0,0,IF('BD Start'!F12-(-SUM(Actual!$B12:$G12))<0,0,'BD Start'!F12-(-SUM(Actual!$B12:$G12)))) -> 9.85 | G12: =IF('BD Start'!G12=0,0,IF('BD Start'!G12-(-Actual!$N12)<0,0,'BD Start'!G12-(-Actual!$N12))) -> 130.38 | H12: =IF('BD Start'!H12=0,0,IF('BD Start'!H12-(-Actual!$H12)<0,0,'BD Start'!H12-(-Actual!$H12))) -> 195.48 | I12: =IF('BD Start'!I12=0,0,IF('BD Start'!I12-(-SUM(Actual!$O12:$P12))<0,0,'BD Start'!I12-(-SUM(Actual!$O12:$P12)))) -> 613.59 | J12: =IF('BD Start'!J12=0,0,IF('BD Start'!J12-(-Actual!$AA12)<0,0,'BD Start'!J12-(-Actual!$AA12))) -> 0 | K12: =IF('BD Start'!K12=0,0,IF('BD Start'!K12-('DATA-CMD'!D12)<0,0,'BD Start'!K12-('DATA-CMD'!D12))) -> 206.4 | L12: =IF('BD Start'!L12=0,0,IF('BD Start'!L12-(Actual!$AB12)<0,0,'BD Start'!L12-(Actual!$AB12))) -> 259.78 | M12: =IF('BD Start'!M12>0,IF(('BD Start'!M12-'DATA-CMD'!L12+TPCIL!O22)>=125,125,IF(('BD Start'!M12-'DATA-CMD'!L12+TPCIL!O22)<0,0,('BD Start'!M12-'DATA-CMD'!L12+TPCIL!O22))),0) -> 0 | N12: =IF('BD Start'!N12=0,0,IF('BD Start'!N12-O12<0,0,'BD Start'!N12-O12)) -> 155.05 | O12: ='DATA-CMD'!L12+TPCIL!E22+TPCIL!F22+TPCIL!G22+TPCIL!H22 -> 346.95 | P12: ='BD Start'!P12+'BD Start'!Q12-'DATA-CMD'!M12 -> 0
A13: 11 | B13: 02:30-02:45 | C13: =IF('BD Start'!C13=0,0,IF('BD Start'!C13-(-SUM(Actual!$I13:$J13))<0,0,'BD Start'!C13-(-SUM(Actual!$I13:$J13)))) -> 50.86 | D13: =IF('BD Start'!D13=0,0,IF('BD Start'!D13-(-SUM(Actual!$K13:$L13))<0,0,'BD Start'!D13-(-SUM(Actual!$K13:$L13)))) -> 171.15 | E13: =IF('BD Start'!E13=0,0,IF('BD Start'!E13-(-Actual!$M13)<0,0,'BD Start'!E13-(-Actual!$M13))) -> 69.08 | F13: =IF('BD Start'!F13=0,0,IF('BD Start'!F13-(-SUM(Actual!$B13:$G13))<0,0,'BD Start'!F13-(-SUM(Actual!$B13:$G13)))) -> 10.66 | G13: =IF('BD Start'!G13=0,0,IF('BD Start'!G13-(-Actual!$N13)<0,0,'BD Start'!G13-(-Actual!$N13))) -> 129.25 | H13: =IF('BD Start'!H13=0,0,IF('BD Start'!H13-(-Actual!$H13)<0,0,'BD Start'!H13-(-Actual!$H13))) -> 198.32 | I13: =IF('BD Start'!I13=0,0,IF('BD Start'!I13-(-SUM(Actual!$O13:$P13))<0,0,'BD Start'!I13-(-SUM(Actual!$O13:$P13)))) -> 617.35 | J13: =IF('BD Start'!J13=0,0,IF('BD Start'!J13-(-Actual!$AA13)<0,0,'BD Start'!J13-(-Actual!$AA13))) -> 0 | K13: =IF('BD Start'!K13=0,0,IF('BD Start'!K13-('DATA-CMD'!D13)<0,0,'BD Start'!K13-('DATA-CMD'!D13))) -> 206.78 | L13: =IF('BD Start'!L13=0,0,IF('BD Start'!L13-(Actual!$AB13)<0,0,'BD Start'!L13-(Actual!$AB13))) -> 248.44 | M13: =IF('BD Start'!M13>0,IF(('BD Start'!M13-'DATA-CMD'!L13+TPCIL!O23)>=125,125,IF(('BD Start'!M13-'DATA-CMD'!L13+TPCIL!O23)<0,0,('BD Start'!M13-'DATA-CMD'!L13+TPCIL!O23))),0) -> 0 | N13: =IF('BD Start'!N13=0,0,IF('BD Start'!N13-O13<0,0,'BD Start'!N13-O13)) -> 155.09 | O13: ='DATA-CMD'!L13+TPCIL!E23+TPCIL!F23+TPCIL!G23+TPCIL!H23 -> 346.91 | P13: ='BD Start'!P13+'BD Start'!Q13-'DATA-CMD'!M13 -> 0
A14: 12 | B14: 02:45-03:00 | C14: =IF('BD Start'!C14=0,0,IF('BD Start'!C14-(-SUM(Actual!$I14:$J14))<0,0,'BD Start'!C14-(-SUM(Actual!$I14:$J14)))) -> 50.21 | D14: =IF('BD Start'!D14=0,0,IF('BD Start'!D14-(-SUM(Actual!$K14:$L14))<0,0,'BD Start'!D14-(-SUM(Actual!$K14:$L14)))) -> 172.35 | E14: =IF('BD Start'!E14=0,0,IF('BD Start'!E14-(-Actual!$M14)<0,0,'BD Start'!E14-(-Actual!$M14))) -> 70.03 | F14: =IF('BD Start'!F14=0,0,IF('BD Start'!F14-(-SUM(Actual!$B14:$G14))<0,0,'BD Start'!F14-(-SUM(Actual!$B14:$G14)))) -> 8.44 | G14: =IF('BD Start'!G14=0,0,IF('BD Start'!G14-(-Actual!$N14)<0,0,'BD Start'!G14-(-Actual!$N14))) -> 135.87 | H14: =IF('BD Start'!H14=0,0,IF('BD Start'!H14-(-Actual!$H14)<0,0,'BD Start'!H14-(-Actual!$H14))) -> 194.96 | I14: =IF('BD Start'!I14=0,0,IF('BD Start'!I14-(-SUM(Actual!$O14:$P14))<0,0,'BD Start'!I14-(-SUM(Actual!$O14:$P14)))) -> 614.9 | J14: =IF('BD Start'!J14=0,0,IF('BD Start'!J14-(-Actual!$AA14)<0,0,'BD Start'!J14-(-Actual!$AA14))) -> 0 | K14: =IF('BD Start'!K14=0,0,IF('BD Start'!K14-('DATA-CMD'!D14)<0,0,'BD Start'!K14-('DATA-CMD'!D14))) -> 205.6 | L14: =IF('BD Start'!L14=0,0,IF('BD Start'!L14-(Actual!$AB14)<0,0,'BD Start'!L14-(Actual!$AB14))) -> 252.05 | M14: =IF('BD Start'!M14>0,IF(('BD Start'!M14-'DATA-CMD'!L14+TPCIL!O24)>=125,125,IF(('BD Start'!M14-'DATA-CMD'!L14+TPCIL!O24)<0,0,('BD Start'!M14-'DATA-CMD'!L14+TPCIL!O24))),0) -> 0 | N14: =IF('BD Start'!N14=0,0,IF('BD Start'!N14-O14<0,0,'BD Start'!N14-O14)) -> 156.17 | O14: ='DATA-CMD'!L14+TPCIL!E24+TPCIL!F24+TPCIL!G24+TPCIL!H24 -> 345.83 | P14: ='BD Start'!P14+'BD Start'!Q14-'DATA-CMD'!M14 -> 0
... A98: 96 | B98: 23:45-24:00 | C98: =IF('BD Start'!C98=0,0,IF('BD Start'!C98-(-SUM(Actual!$I98:$J98))<0,0,'BD Start'!C98-(-SUM(Actual!$I98:$J98)))) -> 63.89 | D98: =IF('BD Start'!D98=0,0,IF('BD Start'!D98-(-SUM(Actual!$K98:$L98))<0,0,'BD Start'!D98-(-SUM(Actual!$K98:$L98)))) -> 151.62 | E98: =IF('BD Start'!E98=0,0,IF('BD Start'!E98-(-Actual!$M98)<0,0,'BD Start'!E98-(-Actual!$M98))) -> 64.74 | F98: =IF('BD Start'!F98=0,0,IF('BD Start'!F98-(-SUM(Actual!$B98:$G98))<0,0,'BD Start'!F98-(-SUM(Actual!$B98:$G98)))) -> 72.8 | G98: =IF('BD Start'!G98=0,0,IF('BD Start'!G98-(-Actual!$N98)<0,0,'BD Start'!G98-(-Actual!$N98))) -> 153.73 | H98: =IF('BD Start'!H98=0,0,IF('BD Start'!H98-(-Actual!$H98)<0,0,'BD Start'!H98-(-Actual!$H98))) -> 164.3 | I98: =IF('BD Start'!I98=0,0,IF('BD Start'!I98-(-SUM(Actual!$O98:$P98))<0,0,'BD Start'!I98-(-SUM(Actual!$O98:$P98)))) -> 386.01 | J98: =IF('BD Start'!J98=0,0,IF('BD Start'!J98-(-Actual!$AA98)<0,0,'BD Start'!J98-(-Actual!$AA98))) -> 0 | K98: =IF('BD Start'!K98=0,0,IF('BD Start'!K98-('DATA-CMD'!D98)<0,0,'BD Start'!K98-('DATA-CMD'!D98))) -> 205.93 | L98: =IF('BD Start'!L98=0,0,IF('BD Start'!L98-(Actual!$AB98)<0,0,'BD Start'!L98-(Actual!$AB98))) -> 0 | M98: =IF('BD Start'!M98>0,IF(('BD Start'!M98-'DATA-CMD'!L98+TPCIL!O108)>=125,125,IF(('BD Start'!M98-'DATA-CMD'!L98+TPCIL!O108)<0,0,('BD Start'!M98-'DATA-CMD'!L98+TPCIL!O108))),0) -> 0 | N98: =IF('BD Start'!N98=0,0,IF('BD Start'!N98-O98<0,0,'BD Start'!N98-O98)) -> 0 | O98: ='DATA-CMD'!L98+TPCIL!E108+TPCIL!F108+TPCIL!G108+TPCIL!H108 -> 500.38 | P98: ='BD Start'!P98+'BD Start'!Q98-'DATA-CMD'!M98 -> 0
B100: Total (MU ) | C100: =SUM(C3:C98)/4000 -> 0.90982 | D100: =SUM(D3:D98)/4000 -> 2.7461925 | E100: =SUM(E3:E98)/4000 -> 1.1214475 | F100: =SUM(F3:F98)/4000 -> 0.3124825 | G100: =SUM(G3:G98)/4000 -> 1.8928125 | H100: =SUM(H3:H98)/4000 -> 2.6170925 | I100: =SUM(I3:I98)/4000 -> 4.4243425 | J100: =SUM(J3:J98)/4000 -> 0 | ... N100: =SUM(N3:N98)/4000 -> 0.34669
E102: =SUM('BD&LR'!C3:C98)/4000 -> 14.70867
E103: =SUM('BD&LR'!D3:D98)/4000 -> 9.0232677
E104: =SUM(E102:E103) -> 23.731938
B109: Minimum | C109: =MIN(C3:C98) -> 0 | D109: =MIN(D3:D98) -> 0 | E109: =MIN(E3:E98) -> 0 | F109: =MIN(F3:F98) -> 0 | G109: =MIN(G3:G98) -> 0 | H109: =MIN(H3:H98) -> 0 | I109: =MIN(I3:I98) -> 0 | J109: =MIN(J3:J98) -> 0 | ... N109: =MIN(N3:N98) -> 0
B110: Maximum | C110: =MAX(C3:C98) -> 75.48 | D110: =MAX(D3:D98) -> 174.39 | E110: =MAX(E3:E98) -> 71.86 | F110: =MAX(F3:F98) -> 72.8 | G110: =MAX(G3:G98) -> 162.75 | H110: =MAX(H3:H98) -> 225.31 | I110: =MAX(I3:I98) -> 621.88 | J110: =MAX(J3:J98) -> 0 | ... N110: =MAX(N3:N98) -> 157.48
C113: =+C100+E100+H100+D100 -> 7.3945525 | E113: =J100+L100 -> 0.68448 | K113: =J100+#REF!+L100 -> #REF!
B118: Date | C118: ='IND-GEN'!X3 -> 12/01/2026
B119: Generating Station | C119: BD. Quantum (MU) | D119: RSD BD (MU)
B120: RTPP | C120: =C100+G100+D100+E100 -> 6.6702725 | D120: =(0)*24/1000 -> 0
B121: VTPS | C121: =H100+F100+L100 -> 3.614055 | D121: =('BD Start'!H99)*24/1000 -> 0
B122: Krishnapatnam | C122: =I100+J100 -> 4.4243425 | D122: 0
B123: Total (MU) | C123: =SUM(C120:C122) -> 14.70867 | D123: =SUM(D120:D122) -> 0

Sheet BD Start
A2: Block | B2: HOUR | C2: RTPP Stg - I | D2: RTPP Stg - II | E2: RTPP Stg - III | F2: VTS (1-6) | G2: RTPP Stg - IV | H2: VTPS - IV | I2: K'Patnam Stg - I | J2: K'Patnam Stg - II | K2: Hinduja | L2: VTPS - V | M2: SEIL-P2-125 | N2: SEIL-P2-502 | P2: SEIL-125 MW DC | Q2: SEIL-500 MW DC
A3: 1 | B3: 00:00-00:15 | C3: 336 | D3: 403 | E3: 194 | F3: 578 | G3: 441 | H3: 460 | I3: 1430 | K3: 750 | V3: 0 | W3: =N3+V3 -> 0
A4: 2 | B4: 00:15-00:30 | C4: 336 | D4: 403 | E4: 194 | F4: 578 | G4: 441 | H4: 460 | I4: 1430 | K4: 750 | V4: 0 | W4: =N4+V4 -> 0
A5: 3 | B5: 00:30-00:45 | C5: 336 | D5: 403 | E5: 194 | F5: 578 | G5: 441 | H5: 460 | I5: 1430 | K5: 750 | V5: 0 | W5: =N5+V5 -> 0 | Y5: -24.62 | Z5: =K5-Y5 -> 774.62
A6: 4 | B6: 00:45-01:00 | C6: 336 | D6: 403 | E6: 194 | F6: 578 | G6: 441 | H6: 460 | I6: 1430 | K6: 750 | U6: =F6-T6 -> 578 | V6: 0 | W6: =N6+V6 -> 0 | Y6: -86.7 | Z6: =K6-Y6 -> 836.7
A7: 5 | B7: 01:00-01:15 | C7: 336 | D7: 403 | E7: 194 | F7: 578 | G7: 441 | H7: 460 | I7: 1430 | K7: 750 | U7: =F7-T7 -> 578 | V7: 0 | W7: =N7+V7 -> 0 | Y7: -127.42 | Z7: =K7-Y7 -> 877.42
A8: 6 | B8: 01:15-01:30 | C8: 336 | D8: 403 | E8: 194 | F8: 578 | G8: 441 | H8: 460 | I8: 1430 | K8: 750 | N8: 502 | U8: =F8-T8 -> 578 | V8: 0 | W8: =N8+V8 -> 502 | Y8: -184.64 | Z8: =K8-Y8 -> 934.64
A9: 7 | B9: 01:30-01:45 | C9: 336 | D9: 403 | E9: 194 | F9: 578 | G9: 441 | H9: 460 | I9: 1430 | K9: 750 | L9: 671 | N9: 502 | U9: =F9-T9 -> 578 | V9: 0 | W9: =N9+V9 -> 502 | Y9: -190.22 | Z9: =K9-Y9 -> 940.22
A10: 8 | B10: 01:45-02:00 | C10: 336 | D10: 403 | E10: 194 | F10: 578 | G10: 441 | H10: 460 | I10: 1430 | K10: 750 | L10: 671 | N10: 502 | V10: 0 | W10: =N10+V10 -> 502 | Y10: -234.36 | Z10: =K10-Y10 -> 984.36
A11: 9 | B11: 02:00-02:15 | C11: 336 | D11: 403 | E11: 194 | F11: 578 | G11: 441 | H11: 460 | I11: 1430 | K11: 750 | L11: 671 | N11: 502 | V11: 0 | W11: =N11+V11 -> 502 | Y11: -246.05 | Z11: =K11-Y11 -> 996.05
A12: 10 | B12: 02:15-02:30 | C12: 336 | D12: 403 | E12: 194 | F12: 578 | G12: 441 | H12: 460 | I12: 1430 | K12: 750 | L12: 671 | N12: 502 | V12: 0 | W12: =N12+V12 -> 502 | Y12: -246.39
A13: 11 | B13: 02:30-02:45 | C13: 336 | D13: 403 | E13: 194 | F13: 578 | G13: 441 | H13: 460 | I13: 1430 | K13: 750 | L13: 671 | N13: 502 | V13: 0 | W13: =N13+V13 -> 502 | Y13: -249.05
A14: 12 | B14: 02:45-03:00 | C14: 336 | D14: 403 | E14: 194 | F14: 578 | G14: 441 | H14: 460 | I14: 1430 | K14: 750 | L14: 671 | N14: 502 | V14: 0 | W14: =N14+V14 -> 502 | Y14: -257.6
A15: 13 | B15: 03:00-03:15 | C15: 336 | D15: 403 | E15: 194 | F15: 578 | G15: 441 | H15: 460 | I15: 1430 | K15: 750 | L15: 671 | N15: 502 | V15: 0 | W15: =N15+V15 -> 502
A16: 14 | B16: 03:15-03:30 | C16: 336 | D16: 403 | E16: 194 | F16: 578 | G16: 441 | H16: 460 | I16: 1430 | K16: 750 | L16: 671 | N16: 502 | V16: 0 | W16: =N16+V16 -> 502
A17: 15 | B17: 03:30-03:45 | C17: 336 | D17: 403 | E17: 194 | F17: 578 | G17: 441 | H17: 460 | I17: 1430 | K17: 750 | L17: 671 | N17: 502 | V17: 0 | W17: =N17+V17 -> 502
A18: 16 | B18: 03:45-04:00 | C18: 336 | D18: 403 | E18: 194 | F18: 578 | G18: 441 | H18: 460 | I18: 1430 | K18: 750 | L18: 671 | V18: 0 | W18: =N18+V18 -> 0
A19: 17 | B19: 04:00-04:15 | C19: 336 | D19: 403 | E19: 194 | F19: 578 | G19: 441 | H19: 460 | I19: 1430 | K19: 750 | L19: 671 | V19: 0 | W19: =N19+V19 -> 0
A20: 18 | B20: 04:15-04:30 | C20: 336 | D20: 403 | E20: 194 | F20: 578 | G20: 441 | H20: 460 | I20: 1430 | K20: 750 | V20: 0 | W20: =N20+V20 -> 0
A21: 19 | B21: 04:30-04:45 | C21: 336 | D21: 403 | E21: 194 | F21: 578 | G21: 441 | H21: 460 | I21: 1430 | K21: 750 | V21: 0 | W21: =N21+V21 -> 0
A22: 20 | B22: 04:45-05:00 | C22: 336 | D22: 403 | E22: 194 | F22: 578 | G22: 441 | H22: 460 | I22: 1430 | K22: 750 | V22: 0 | W22: =N22+V22 -> 0
A23: 21 | B23: 05:00-05:15 | C23: 336 | D23: 403 | E23: 194 | F23: 578 | G23: 441 | H23: 460 | I23: 1430 | K23: 750 | V23: 0 | W23: =N23+V23 -> 0
A24: 22 | B24: 05:15-05:30 | C24: 336 | D24: 403 | E24: 194 | F24: 578 | G24: 441 | H24: 460 | V24: 0 | W24: =N24+V24 -> 0
A25: 23 | B25: 05:30-05:45 | C25: 336 | D25: 403 | E25: 194 | F25: 578 | G25: 441 | H25: 460 | V25: 0 | W25: =N25+V25 -> 0
A26: 24 | B26: 05:45-06:00 | C26: 336 | D26: 403 | E26: 194 | F26: 578 | G26: 441 | H26: 460 | V26: 0 | W26: =N26+V26 -> 0
A27: 25 | B27: 06:00-06:15 | C27: 336 | D27: 403 | E27: 194 | F27: 578 | G27: 441 | H27: 460 | V27: 0 | W27: =N27+V27 -> 0
A28: 26 | B28: 06:15-06:30 | C28: 336 | D28: 403 | E28: 194 | V28: 51 | W28: =N28+V28 -> 51
A29: 27 | B29: 06:30-06:45 | C29: 336 | D29: 403 | E29: 194 | V29: 103 | W29: =N29+V29 -> 103
A30: 28 | B30: 06:45-07:00 | C30: 336 | D30: 403 | E30: 194 | F30: 578 | G30: 450 | H30: 460 | V30: 125 | W30: =N30+V30 -> 125
A31: 29 | B31: 07:00-07:15 | C31: 336 | D31: 403 | E31: 194 | F31: 578 | G31: 450 | H31: 460 | V31: 125 | W31: =N31+V31 -> 125
A32: 30 | B32: 07:15-07:30 | C32: 336 | D32: 403 | E32: 194 | F32: 578 | G32: 450 | H32: 460 | U32: =J32-T32 -> 0 | V32: 125 | W32: =N32+V32 -> 125
A33: 31 | B33: 07:30-07:45 | C33: 336 | D33: 403 | E33: 194 | F33: 578 | G33: 450 | H33: 460 | U33: =J33-T33 -> 0 | V33: 125 | W33: =N33+V33 -> 125
A34: 32 | B34: 07:45-08:00 | C34: 336 | D34: 403 | E34: 194 | U34: =J34-T34 -> 0 | V34: 125 | W34: =N34+V34 -> 125 | AA34: -8.46 | AB34: =+#REF!-AA34 -> #REF!
A35: 33 | B35: 08:00-08:15 | U35: =J35-T35 -> 0 | V35: 125 | W35: =N35+V35 -> 125 | AA35: -56.19 | AB35: =+#REF!-AA35 -> #REF!
A36: 34 | B36: 08:15-08:30 | U36: =J36-T36 -> 0 | V36: 125 | W36: =N36+V36 -> 125 | AA36: -59.49 | AB36: =+#REF!-AA36 -> #REF!
A37: 35 | B37: 08:30-08:45 | U37: =J37-T37 -> 0 | V37: 125 | W37: =N37+V37 -> 125 | AA37: -55.03 | AB37: =+#REF!-AA37 -> #REF!
A38: 36 | B38: 08:45-09:00 | U38: =J38-T38 -> 0 | V38: 125 | W38: =N38+V38 -> 125 | AA38: -65.49 | AB38: =+#REF!-AA38 -> #REF!
A39: 37 | B39: 09:00-09:15 | U39: =J39-T39 -> 0 | V39: 125 | W39: =N39+V39 -> 125 | AA39: -93.33 | AB39: =+#REF!-AA39 -> #REF!
A40: 38 | B40: 09:15-09:30 | U40: =J40-T40 -> 0 | V40: 125 | W40: =N40+V40 -> 125 | AA40: -100.43 | AB40: =+#REF!-AA40 -> #REF!
A41: 39 | B41: 09:30-09:45 | C41: 327 | D41: 405 | E41: 195 | F41: 540 | G41: 440 | U41: =J41-T41 -> 0 | V41: 125 | W41: =N41+V41 -> 125 | AA41: -96.54 | AB41: =+#REF!-AA41 -> #REF!
...

Sheet CGS BD CAL
O1: OFF BAR Availed power from ISGS
A2: Time Block | B2: Time Desc | C2: TOTAL ENTITLEMENT (SHEET) | D2: TOTAL OFF BAR ENTITLEMENT | E2: TOTAL ENTITILEMENT (ON BAR) | F2: AP AREA ISGS( SIM-I Only) | G2: NET Entitlememnt exclude SIM-I | H2: NET Entitlement (excluded Offbar availed power) | I2: Final Entitlement (Net entl.+ OFF bar availed) | J2: ACTUAL SCHEDULE | K2: ISGS B/D | L2: TPCIL B/D 230.55 MW + 468 MW | M2: TOTAL B/D | O2: KUDGI OFFBAR AVAILED | P2: RGM(1-6) OFFBAR AVAILED | Q2: RGM-7 OFFBAR AVAILED | R2: VALLUR OFFBAR AVAILED | S2: SIM-I OFF BAR AVAILED | T2: SIM-II OFF BAR AVAILED | U2: TALCHER OFF BAR AVAILED | V2: NLC II OFF BAR AVALIED | W2: TSTPP OFF BAR AVAILED | X2: TOTAL OFF BARS AVAILED
A3: 1 | B3: 00:00-00:15 | C3: =Entitlement!BC7 -> 1625.01 | D3: =(Entitlement!L7+Entitlement!Q7+Entitlement!T7+Entitlement!W7+Entitlement!Z7+Entitlement!AC7+Entitlement!AF7+Entitlement!AI7+Entitlement!AL7+Entitlement!AO7+Entitlement!AR7+Entitlement!AU7+Entitlement!AX7+Entitlement!BA7) -> 17.44 | E3: =C3-D3 -> 1607.57 | F3: =ISGS!Q13 -> 216.14 | G3: =E3-F3 -> 1391.43 | H3: =G3*(1-TPCIL!$L$11)+F3 -> 1540.6422 | I3: =H3+X3 -> 1540.6422 | J3: =ISGS!V13 -> 520.33 | K3: =I3-J3 -> 1020.3122 | L3: =(TPCIL!I13-TPCIL!C13)+(TPCIL!P13-TPCIL!D13) -> 0.000545 | M3: =+L3+K3 -> 1020.3128 | O3: =IF(ISGS!G13-Entitlement!K7*(1-TPCIL!$L$11)<0,0,ISGS!G13-Entitlement!K7*(1-TPCIL!$L$11)) -> 0 | P3: =IF(ISGS!O13-Entitlement!AH7*(1-TPCIL!$L$11)<0,0,ISGS!O13-Entitlement!AH7*(1-TPCIL!$L$11)) -> 0 | Q3: =IF(ISGS!P13-Entitlement!AK7*(1-TPCIL!$L$11)<0,0,ISGS!P13-Entitlement!AK7*(1-TPCIL!$L$11)) -> 0 | R3: =IF(ISGS!U13-Entitlement!AZ7*(1-TPCIL!$L$11)<0,0,ISGS!U13-Entitlement!AZ7*(1-TPCIL!$L$11)) -> 0 | S3: =IF(ISGS!Q13-Entitlement!AN7<0,0,ISGS!Q13-Entitlement!AN7) -> 0 | T3: =IF(ISGS!R13-Entitlement!AQ7*(1-TPCIL!$L$11)<0,0,ISGS!R13-Entitlement!AQ7*(1-TPCIL!$L$11)) -> 0 | U3: =IF(ISGS!S13-Entitlement!AT7*(1-TPCIL!$L$11)<0,0,ISGS!S13-Entitlement!AT7*(1-TPCIL!$L$11)) -> 0 | V3: =IF(ISGS!K13-Entitlement!V7*(1-TPCIL!$L$11)<0,0,ISGS!K13-Entitlement!V7*(1-TPCIL!$L$11)) -> 0 | X3: =SUM(O3:W3) -> 0
A4: 2 | B4: 00:15-00:30 | C4: =Entitlement!BC8 -> 1625.01 | D4: =(Entitlement!L8+Entitlement!Q8+Entitlement!T8+Entitlement!W8+Entitlement!Z8+Entitlement!AC8+Entitlement!AF8+Entitlement!AI8+Entitlement!AL8+Entitlement!AO8+Entitlement!AR8+Entitlement!AU8+Entitlement!AX8+Entitlement!BA8) -> 17.44 | E4: =C4-D4 -> 1607.57 | F4: =ISGS!Q14 -> 216.14 | G4: =E4-F4 -> 1391.43 | H4: =G4*(1-TPCIL!$L$11)+F4 -> 1540.6422 | I4: =H4+X4 -> 1540.6422 | J4: =ISGS!V14 -> 520.37 | K4: =I4-J4 -> 1020.2722 | L4: =(TPCIL!I14-TPCIL!C14)+(TPCIL!P14-TPCIL!D14) -> 0.000545 | M4: =+L4+K4 -> 1020.2728 | O4: =IF(ISGS!G14-Entitlement!K8*(1-TPCIL!$L$11)<0,0,ISGS!G14-Entitlement!K8*(1-TPCIL!$L$11)) -> 0 | P4: =IF(ISGS!O14-Entitlement!AH8*(1-TPCIL!$L$11)<0,0,ISGS!O14-Entitlement!AH8*(1-TPCIL!$L$11)) -> 0 | Q4: =IF(ISGS!P14-Entitlement!AK8*(1-TPCIL!$L$11)<0,0,ISGS!P14-Entitlement!AK8*(1-TPCIL!$L$11)) -> 0 | R4: =IF(ISGS!U14-Entitlement!AZ8*(1-TPCIL!$L$11)<0,0,ISGS!U14-Entitlement!AZ8*(1-TPCIL!$L$11)) -> 0 | S4: =IF(ISGS!Q14-Entitlement!AN8<0,0,ISGS!Q14-Entitlement!AN8) -> 0 | T4: =IF(ISGS!R14-Entitlement!AQ8*(1-TPCIL!$L$11)<0,0,ISGS!R14-Entitlement!AQ8*(1-TPCIL!$L$11)) -> 0 | U4: =IF(ISGS!S14-Entitlement!AT8<0,0,ISGS!S14-Entitlement!AT8) -> 0 | V4: =IF(ISGS!K14-Entitlement!V8*(1-TPCIL!$L$11)<0,0,ISGS!K14-Entitlement!V8*(1-TPCIL!$L$11)) -> 0 | X4: =SUM(O4:W4) -> 0
A5: 3 | B5: 00:30-00:45 | C5: =Entitlement!BC9 -> 1625.01 | D5: =(Entitlement!L9+Entitlement!Q9+Entitlement!T9+Entitlement!W9+Entitlement!Z9+Entitlement!AC9+Entitlement!AF9+Entitlement!AI9+Entitlement!AL9+Entitlement!AO9+Entitlement!AR9+Entitlement!AU9+Entitlement!AX9+Entitlement!BA9) -> 17.44 | E5: =C5-D5 -> 1607.57 | F5: =ISGS!Q15 -> 216.14 | G5: =E5-F5 -> 1391.43 | H5: =G5*(1-TPCIL!$L$11)+F5 -> 1540.6422 | I5: =H5+X5 -> 1540.6422 | J5: =ISGS!V15 -> 520.37 | K5: =I5-J5 -> 1020.2722 | L5: =(TPCIL!I15-TPCIL!C15)+(TPCIL!P15-TPCIL!D15) -> 0.000545 | M5: =+L5+K5 -> 1020.2728 | O5: =IF(ISGS!G15-Entitlement!K9*(1-TPCIL!$L$11)<0,0,ISGS!G15-Entitlement!K9*(1-TPCIL!$L$11)) -> 0 | P5: =IF(ISGS!O15-Entitlement!AH9*(1-TPCIL!$L$11)<0,0,ISGS!O15-Entitlement!AH9*(1-TPCIL!$L$11)) -> 0 | Q5: =IF(ISGS!P15-Entitlement!AK9*(1-TPCIL!$L$11)<0,0,ISGS!P15-Entitlement!AK9*(1-TPCIL!$L$11)) -> 0 | R5: =IF(ISGS!U15-Entitlement!AZ9*(1-TPCIL!$L$11)<0,0,ISGS!U15-Entitlement!AZ9*(1-TPCIL!$L$11)) -> 0 | S5: =IF(ISGS!Q15-Entitlement!AN9<0,0,ISGS!Q15-Entitlement!AN9) -> 0 | T5: =IF(ISGS!R15-Entitlement!AQ9*(1-TPCIL!$L$11)<0,0,ISGS!R15-Entitlement!AQ9*(1-TPCIL!$L$11)) -> 0 | U5: =IF(ISGS!S15-Entitlement!AT9<0,0,ISGS!S15-Entitlement!AT9) -> 0 | V5: =IF(ISGS!K15-Entitlement!V9*(1-TPCIL!$L$11)<0,0,ISGS!K15-Entitlement!V9*(1-TPCIL!$L$11)) -> 0 | X5: =SUM(O5:W5) -> 0
A6: 4 | B6: 00:45-01:00 | C6: =Entitlement!BC10 -> 1625.01 | D6: =(Entitlement!L10+Entitlement!Q10+Entitlement!T10+Entitlement!W10+Entitlement!Z10+Entitlement!AC10+Entitlement!AF10+Entitlement!AI10+Entitlement!AL10+Entitlement!AO10+Entitlement!AR10+Entitlement!AU10+Entitlement!AX10+Entitlement!BA10) -> 17.44 | E6: =C6-D6 -> 1607.57 | F6: =ISGS!Q16 -> 216.14 | G6: =E6-F6 -> 1391.43 | H6: =G6*(1-TPCIL!$L$11)+F6 -> 1540.6422 | I6: =H6+X6 -> 1540.6422 | J6: =ISGS!V16 -> 520.37 | K6: =I6-J6 -> 1020.2722 | L6: =(TPCIL!I16-TPCIL!C16)+(TPCIL!P16-TPCIL!D16) -> 0.000545 | M6: =+L6+K6 -> 1020.2728 | O6: =IF(ISGS!G16-Entitlement!K10*(1-TPCIL!$L$11)<0,0,ISGS!G16-Entitlement!K10*(1-TPCIL!$L$11)) -> 0 | P6: =IF(ISGS!O16-Entitlement!AH10*(1-TPCIL!$L$11)<0,0,ISGS!O16-Entitlement!AH10*(1-TPCIL!$L$11)) -> 0 | Q6: =IF(ISGS!P16-Entitlement!AK10*(1-TPCIL!$L$11)<0,0,ISGS!P16-Entitlement!AK10*(1-TPCIL!$L$11)) -> 0 | R6: =IF(ISGS!U16-Entitlement!AZ10*(1-TPCIL!$L$11)<0,0,ISGS!U16-Entitlement!AZ10*(1-TPCIL!$L$11)) -> 0 | S6: =IF(ISGS!Q16-Entitlement!AN10<0,0,ISGS!Q16-Entitlement!AN10) -> 0 | T6: =IF(ISGS!R16-Entitlement!AQ10*(1-TPCIL!$L$11)<0,0,ISGS!R16-Entitlement!AQ10*(1-TPCIL!$L$11)) -> 0 | U6: =IF(ISGS!S16-Entitlement!AT10<0,0,ISGS!S16-Entitlement!AT10) -> 0 | V6: =IF(ISGS!K16-Entitlement!V10*(1-TPCIL!$L$11)<0,0,ISGS!K16-Entitlement!V10*(1-TPCIL!$L$11)) -> 0 | X6: =SUM(O6:W6) -> 0
A7: 5 | B7: 01:00-01:15 | C7: =Entitlement!BC11 -> 1625.01 | D7: =(Entitlement!L11+Entitlement!Q11+Entitlement!T11+Entitlement!W11+Entitlement!Z11+Entitlement!AC11+Entitlement!AF11+Entitlement!AI11+Entitlement!AL11+Entitlement!AO11+Entitlement!AR11+Entitlement!AU11+Entitlement!AX11+Entitlement!BA11) -> 17.44 | E7: =C7-D7 -> 1607.57 | F7: =ISGS!Q17 -> 216.14 | G7: =E7-F7 -> 1391.43 | H7: =G7*(1-TPCIL!$L$11)+F7 -> 1540.6422 | I7: =H7+X7 -> 1540.6422 | J7: =ISGS!V17 -> 520.37 | K7: =I7-J7 -> 1020.2722 | L7: =(TPCIL!I17-TPCIL!C17)+(TPCIL!P17-TPCIL!D17) -> 0.000545 | M7: =+L7+K7 -> 1020.2728 | O7: =IF(ISGS!G17-Entitlement!K11*(1-TPCIL!$L$11)<0,0,ISGS!G17-Entitlement!K11*(1-TPCIL!$L$11)) -> 0 | P7: =IF(ISGS!O17-Entitlement!AH11*(1-TPCIL!$L$11)<0,0,ISGS!O17-Entitlement!AH11*(1-TPCIL!$L$11)) -> 0 | Q7: =IF(ISGS!P17-Entitlement!AK11*(1-TPCIL!$L$11)<0,0,ISGS!P17-Entitlement!AK11*(1-TPCIL!$L$11)) -> 0 | R7: =IF(ISGS!U17-Entitlement!AZ11*(1-TPCIL!$L$11)<0,0,ISGS!U17-Entitlement!AZ11*(1-TPCIL!$L$11)) -> 0 | S7: =IF(ISGS!Q17-Entitlement!AN11<0,0,ISGS!Q17-Entitlement!AN11) -> 0 | T7: =IF(ISGS!R17-Entitlement!AQ11*(1-TPCIL!$L$11)<0,0,ISGS!R17-Entitlement!AQ11*(1-TPCIL!$L$11)) -> 0 | U7: =IF(ISGS!S17-Entitlement!AT11<0,0,ISGS!S17-Entitlement!AT11) -> 0 | V7: =IF(ISGS!K17-Entitlement!V11*(1-TPCIL!$L$11)<0,0,ISGS!K17-Entitlement!V11*(1-TPCIL!$L$11)) -> 0 | X7: =SUM(O7:W7) -> 0
A8: 6 | B8: 01:15-01:30 | C8: =Entitlement!BC12 -> 1625.01 | D8: =(Entitlement!L12+Entitlement!Q12+Entitlement!T12+Entitlement!W12+Entitlement!Z12+Entitlement!AC12+Entitlement!AF12+Entitlement!AI12+Entitlement!AL12+Entitlement!AO12+Entitlement!AR12+Entitlement!AU12+Entitlement!AX12+Entitlement!BA12) -> 17.44 | E8: =C8-D8 -> 1607.57 | F8: =ISGS!Q18 -> 216.14 | G8: =E8-F8 -> 1391.43 | H8: =G8*(1-TPCIL!$L$11)+F8 -> 1540.6422 | I8: =H8+X8 -> 1540.6422 | J8: =ISGS!V18 -> 520.37 | K8: =I8-J8 -> 1020.2722 | L8: =(TPCIL!I18-TPCIL!C18)+(TPCIL!P18-TPCIL!D18) -> 0.000545 | M8: =+L8+K8 -> 1020.2728 | O8: =IF(ISGS!G18-Entitlement!K12*(1-TPCIL!$L$11)<0,0,ISGS!G18-Entitlement!K12*(1-TPCIL!$L$11)) -> 0 | P8: =IF(ISGS!O18-Entitlement!AH12*(1-TPCIL!$L$11)<0,0,ISGS!O18-Entitlement!AH12*(1-TPCIL!$L$11)) -> 0 | Q8: =IF(ISGS!P18-Entitlement!AK12*(1-TPCIL!$L$11)<0,0,ISGS!P18-Entitlement!AK12*(1-TPCIL!$L$11)) -> 0 | R8: =IF(ISGS!U18-Entitlement!AZ12*(1-TPCIL!$L$11)<0,0,ISGS!U18-Entitlement!AZ12*(1-TPCIL!$L$11)) -> 0 | S8: =IF(ISGS!Q18-Entitlement!AN12<0,0,ISGS!Q18-Entitlement!AN12) -> 0 | T8: =IF(ISGS!R18-Entitlement!AQ12*(1-TPCIL!$L$11)<0,0,ISGS!R18-Entitlement!AQ12*(1-TPCIL!$L$11)) -> 0 | U8: =IF(ISGS!S18-Entitlement!AT12<0,0,ISGS!S18-Entitlement!AT12) -> 0 | V8: =IF(ISGS!K18-Entitlement!V12*(1-TPCIL!$L$11)<0,0,ISGS!K18-Entitlement!V12*(1-TPCIL!$L$11)) -> 0 | X8: =SUM(O8:W8) -> 0
A9: 7 | B9: 01:30-01:45 | C9: =Entitlement!BC13 -> 1625.44 | D9: =(Entitlement!L13+Entitlement!Q13+Entitlement!T13+Entitlement!W13+Entitlement!Z13+Entitlement!AC13+Entitlement!AF13+Entitlement!AI13+Entitlement!AL13+Entitlement!AO13+Entitlement!AR13+Entitlement!AU13+Entitlement!AX13+Entitlement!BA13) -> 17.44 | E9: =C9-D9 -> 1608 | F9: =ISGS!Q19 -> 216.14 | G9: =E9-F9 -> 1391.86 | H9: =G9*(1-TPCIL!$L$11)+F9 -> 1541.0515 | I9: =H9+X9 -> 1541.0515 | J9: =ISGS!V19 -> 510.11 | K9: =I9-J9 -> 1030.9415 | L9: =(TPCIL!I19-TPCIL!C19)+(TPCIL!P19-TPCIL!D19) -> 98.760545 | M9: =+L9+K9 -> 1129.7021 | O9: =IF(ISGS!G19-Entitlement!K13*(1-TPCIL!$L$11)<0,0,ISGS!G19-Entitlement!K13*(1-TPCIL!$L$11)) -> 0 | P9: =IF(ISGS!O19-Entitlement!AH13*(1-TPCIL!$L$11)<0,0,ISGS!O19-Entitlement!AH13*(1-TPCIL!$L$11)) -> 0 | Q9: =IF(ISGS!P19-Entitlement!AK13*(1-TPCIL!$L$11)<0,0,ISGS!P19-Entitlement!AK13*(1-TPCIL!$L$11)) -> 0 | R9: =IF(ISGS!U19-Entitlement!AZ13*(1-TPCIL!$L$11)<0,0,ISGS!U19-Entitlement!AZ13*(1-TPCIL!$L$11)) -> 0 | S9: =IF(ISGS!Q19-Entitlement!AN13<0,0,ISGS!Q19-Entitlement!AN13) -> 0 | T9: =IF(ISGS!R19-Entitlement!AQ13*(1-TPCIL!$L$11)<0,0,ISGS!R19-Entitlement!AQ13*(1-TPCIL!$L$11)) -> 0 | U9: =IF(ISGS!S19-Entitlement!AT13<0,0,ISGS!S19-Entitlement!AT13) -> 0 | V9: =IF(ISGS!K19-Entitlement!V13*(1-TPCIL!$L$11)<0,0,ISGS!K19-Entitlement!V13*(1-TPCIL!$L$11)) -> 0 | X9: =SUM(O9:W9) -> 0
A10: 8 | B10: 01:45-02:00 | C10: =Entitlement!BC14 -> 1625.44 | D10: =(Entitlement!L14+Entitlement!Q14+Entitlement!T14+Entitlement!W14+Entitlement!Z14+Entitlement!AC14+Entitlement!AF14+Entitlement!AI14+Entitlement!AL14+Entitlement!AO14+Entitlement!AR14+Entitlement!AU14+Entitlement!AX14+Entitlement!BA14) -> 17.44 | E10: =C10-D10 -> 1608 | F10: =ISGS!Q20 -> 216.14 | G10: =E10-F10 -> 1391.86 | H10: =G10*(1-TPCIL!$L$11)+F10 -> 1541.0515 | I10: =H10+X10 -> 1541.0515 | J10: =ISGS!V20 -> 495.69 | K10: =I10-J10 -> 1045.3615 | L10: =(TPCIL!I20-TPCIL!C20)+(TPCIL!P20-TPCIL!D20) -> 98.760545 | M10: =+L10+K10 -> 1144.1221 | O10: =IF(ISGS!G20-Entitlement!K14*(1-TPCIL!$L$11)<0,0,ISGS!G20-Entitlement!K14*(1-TPCIL!$L$11)) -> 0 | P10: =IF(ISGS!O20-Entitlement!AH14*(1-TPCIL!$L$11)<0,0,ISGS!O20-Entitlement!AH14*(1-TPCIL!$L$11)) -> 0 | Q10: =IF(ISGS!P20-Entitlement!AK14*(1-TPCIL!$L$11)<0,0,ISGS!P20-Entitlement!AK14*(1-TPCIL!$L$11)) -> 0 | R10: =IF(ISGS!U20-Entitlement!AZ14*(1-TPCIL!$L$11)<0,0,ISGS!U20-Entitlement!AZ14*(1-TPCIL!$L$11)) -> 0 | S10: =IF(ISGS!Q20-Entitlement!AN14<0,0,ISGS!Q20-Entitlement!AN14) -> 0 | T10: =IF(ISGS!R20-Entitlement!AQ14*(1-TPCIL!$L$11)<0,0,ISGS!R20-Entitlement!AQ14*(1-TPCIL!$L$11)) -> 0 | U10: =IF(ISGS!S20-Entitlement!AT14<0,0,ISGS!S20-Entitlement!AT14) -> 0 | V10: =IF(ISGS!K20-Entitlement!V14*(1-TPCIL!$L$11)<0,0,ISGS!K20-Entitlement!V14*(1-TPCIL!$L$11)) -> 0 | X10: =SUM(O10:W10) -> 0
A11: 9 | B11: 02:00-02:15 | C11: =Entitlement!BC15 -> 1625.44 | D11: =(Entitlement!L15+Entitlement!Q15+Entitlement!T15+Entitlement!W15+Entitlement!Z15+Entitlement!AC15+Entitlement!AF15+Entitlement!AI15+Entitlement!AL15+Entitlement!AO15+Entitlement!AR15+Entitlement!AU15+Entitlement!AX15+Entitlement!BA15) -> 17.44 | E11: =C11-D11 -> 1608 | F11: =ISGS!Q21 -> 216.14 | G11: =E11-F11 -> 1391.86 | H11: =G11*(1-TPCIL!$L$11)+F11 -> 1541.0515 | I11: =H11+X11 -> 1541.0515 | J11: =ISGS!V21 -> 495.69 | K11: =I11-J11 -> 1045.3615 | L11: =(TPCIL!I21-TPCIL!C21)+(TPCIL!P21-TPCIL!D21) -> 98.760545 | M11: =+L11+K11 -> 1144.1221 | O11: =IF(ISGS!G21-Entitlement!K15*(1-TPCIL!$L$11)<0,0,ISGS!G21-Entitlement!K15*(1-TPCIL!$L$11)) -> 0 | P11: =IF(ISGS!O21-Entitlement!AH15*(1-TPCIL!$L$11)<0,0,ISGS!O21-Entitlement!AH15*(1-TPCIL!$L$11)) -> 0 | Q11: =IF(ISGS!P21-Entitlement!AK15*(1-TPCIL!$L$11)<0,0,ISGS!P21-Entitlement!AK15*(1-TPCIL!$L$11)) -> 0 | R11: =IF(ISGS!U21-Entitlement!AZ15*(1-TPCIL!$L$11)<0,0,ISGS!U21-Entitlement!AZ15*(1-TPCIL!$L$11)) -> 0 | S11: =IF(ISGS!Q21-Entitlement!AN15<0,0,ISGS!Q21-Entitlement!AN15) -> 0 | T11: =IF(ISGS!R21-Entitlement!AQ15*(1-TPCIL!$L$11)<0,0,ISGS!R21-Entitlement!AQ15*(1-TPCIL!$L$11)) -> 0 | U11: =IF(ISGS!S21-Entitlement!AT15<0,0,ISGS!S21-Entitlement!AT15) -> 0 | V11: =IF(ISGS!K21-Entitlement!V15*(1-TPCIL!$L$11)<0,0,ISGS!K21-Entitlement!V15*(1-TPCIL!$L$11)) -> 0 | X11: =SUM(O11:W11) -> 0
A12: 10 | B12: 02:15-02:30 | C12: =Entitlement!BC16 -> 1625.44 | D12: =(Entitlement!L16+Entitlement!Q16+Entitlement!T16+Entitlement!W16+Entitlement!Z16+Entitlement!AC16+Entitlement!AF16+Entitlement!AI16+Entitlement!AL16+Entitlement!AO16+Entitlement!AR16+Entitlement!AU16+Entitlement!AX16+Entitlement!BA16) -> 17.44 | E12: =C12-D12 -> 1608 | F12: =ISGS!Q22 -> 216.14 | G12: =E12-F12 -> 1391.86 | H12: =G12*(1-TPCIL!$L$11)+F12 -> 1541.0515 | I12: =H12+X12 -> 1541.0515 | J12: =ISGS!V22 -> 495.69 | K12: =I12-J12 -> 1045.3615 | L12: =(TPCIL!I22-TPCIL!C22)+(TPCIL!P22-TPCIL!D22) -> 98.760545 | M12: =+L12+K12 -> 1144.1221 | O12: =IF(ISGS!G22-Entitlement!K16*(1-TPCIL!$L$11)<0,0,ISGS!G22-Entitlement!K16*(1-TPCIL!$L$11)) -> 0 | P12: =IF(ISGS!O22-Entitlement!AH16*(1-TPCIL!$L$11)<0,0,ISGS!O22-Entitlement!AH16*(1-TPCIL!$L$11)) -> 0 | Q12: =IF(ISGS!P22-Entitlement!AK16*(1-TPCIL!$L$11)<0,0,ISGS!P22-Entitlement!AK16*(1-TPCIL!$L$11)) -> 0 | R12: =IF(ISGS!U22-Entitlement!AZ16*(1-TPCIL!$L$11)<0,0,ISGS!U22-Entitlement!AZ16*(1-TPCIL!$L$11)) -> 0 | S12: =IF(ISGS!Q22-Entitlement!AN16<0,0,ISGS!Q22-Entitlement!AN16) -> 0 | T12: =IF(ISGS!R22-Entitlement!AQ16*(1-TPCIL!$L$11)<0,0,ISGS!R22-Entitlement!AQ16*(1-TPCIL!$L$11)) -> 0 | U12: =IF(ISGS!S22-Entitlement!AT16<0,0,ISGS!S22-Entitlement!AT16) -> 0 | V12: =IF(ISGS!K22-Entitlement!V16*(1-TPCIL!$L$11)<0,0,ISGS!K22-Entitlement!V16*(1-TPCIL!$L$11)) -> 0 | X12: =SUM(O12:W12) -> 0
A13: 11 | B13: 02:30-02:45 | C13: =Entitlement!BC17 -> 1625.44 | D13: =(Entitlement!L17+Entitlement!Q17+Entitlement!T17+Entitlement!W17+Entitlement!Z17+Entitlement!AC17+Entitlement!AF17+Entitlement!AI17+Entitlement!AL17+Entitlement!AO17+Entitlement!AR17+Entitlement!AU17+Entitlement!AX17+Entitlement!BA17) -> 17.44 | E13: =C13-D13 -> 1608 | F13: =ISGS!Q23 -> 216.14 | G13: =E13-F13 -> 1391.86 | H13: =G13*(1-TPCIL!$L$11)+F13 -> 1541.0515 | I13: =H13+X13 -> 1541.0515 | J13: =ISGS!V23 -> 495.69 | K13: =I13-J13 -> 1045.3615 | L13: =(TPCIL!I23-TPCIL!C23)+(TPCIL!P23-TPCIL!D23) -> 98.760545 | M13: =+L13+K13 -> 1144.1221 | O13: =IF(ISGS!G23-Entitlement!K17*(1-TPCIL!$L$11)<0,0,ISGS!G23-Entitlement!K17*(1-TPCIL!$L$11)) -> 0 | P13: =IF(ISGS!O23-Entitlement!AH17*(1-TPCIL!$L$11)<0,0,ISGS!O23-Entitlement!AH17*(1-TPCIL!$L$11)) -> 0 | Q13: =IF(ISGS!P23-Entitlement!AK17*(1-TPCIL!$L$11)<0,0,ISGS!P23-Entitlement!AK17*(1-TPCIL!$L$11)) -> 0 | R13: =IF(ISGS!U23-Entitlement!AZ17*(1-TPCIL!$L$11)<0,0,ISGS!U23-Entitlement!AZ17*(1-TPCIL!$L$11)) -> 0 | S13: =IF(ISGS!Q23-Entitlement!AN17<0,0,ISGS!Q23-Entitlement!AN17) -> 0 | T13: =IF(ISGS!R23-Entitlement!AQ17*(1-TPCIL!$L$11)<0,0,ISGS!R23-Entitlement!AQ17*(1-TPCIL!$L$11)) -> 0 | U13: =IF(ISGS!S23-Entitlement!AT17<0,0,ISGS!S23-Entitlement!AT17) -> 0 | V13: =IF(ISGS!K23-Entitlement!V17*(1-TPCIL!$L$11)<0,0,ISGS!K23-Entitlement!V17*(1-TPCIL!$L$11)) -> 0 | X13: =SUM(O13:W13) -> 0
A14: 12 | B14: 02:45-03:00 | C14: =Entitlement!BC18 -> 1625.44 | D14: =(Entitlement!L18+Entitlement!Q18+Entitlement!T18+Entitlement!W18+Entitlement!Z18+Entitlement!AC18+Entitlement!AF18+Entitlement!AI18+Entitlement!AL18+Entitlement!AO18+Entitlement!AR18+Entitlement!AU18+Entitlement!AX18+Entitlement!BA18) -> 17.44 | E14: =C14-D14 -> 1608 | F14: =ISGS!Q24 -> 216.14 | G14: =E14-F14 -> 1391.86 | H14: =G14*(1-TPCIL!$L$11)+F14 -> 1541.0515 | I14: =H14+X14 -> 1541.0515 | J14: =ISGS!V24 -> 495.69 | K14: =I14-J14 -> 1045.3615 | L14: =(TPCIL!I24-TPCIL!C24)+(TPCIL!P24-TPCIL!D24) -> 98.760545 | M14: =+L14+K14 -> 1144.1221 | O14: =IF(ISGS!G24-Entitlement!K18*(1-TPCIL!$L$11)<0,0,ISGS!G24-Entitlement!K18*(1-TPCIL!$L$11)) -> 0 | P14: =IF(ISGS!O24-Entitlement!AH18*(1-TPCIL!$L$11)<0,0,ISGS!O24-Entitlement!AH18*(1-TPCIL!$L$11)) -> 0 | Q14: =IF(ISGS!P24-Entitlement!AK18*(1-TPCIL!$L$11)<0,0,ISGS!P24-Entitlement!AK18*(1-TPCIL!$L$11)) -> 0 | R14: =IF(ISGS!U24-Entitlement!AZ18*(1-TPCIL!$L$11)<0,0,ISGS!U24-Entitlement!AZ18*(1-TPCIL!$L$11)) -> 0 | S14: =IF(ISGS!Q24-Entitlement!AN18<0,0,ISGS!Q24-Entitlement!AN18) -> 0 | T14: =IF(ISGS!R24-Entitlement!AQ18*(1-TPCIL!$L$11)<0,0,ISGS!R24-Entitlement!AQ18*(1-TPCIL!$L$11)) -> 0 | U14: =IF(ISGS!S24-Entitlement!AT18<0,0,ISGS!S24-Entitlement!AT18) -> 0 | V14: =IF(ISGS!K24-Entitlement!V18*(1-TPCIL!$L$11)<0,0,ISGS!K24-Entitlement!V18*(1-TPCIL!$L$11)) -> 0 | X14: =SUM(O14:W14) -> 0
A15: 13 | B15: 03:00-03:15 | C15: =Entitlement!BC19 -> 1625.44 | D15: =(Entitlement!L19+Entitlement!Q19+Entitlement!T19+Entitlement!W19+Entitlement!Z19+Entitlement!AC19+Entitlement!AF19+Entitlement!AI19+Entitlement!AL19+Entitlement!AO19+Entitlement!AR19+Entitlement!AU19+Entitlement!AX19+Entitlement!BA19) -> 17.44 | E15: =C15-D15 -> 1608 | F15: =ISGS!Q25 -> 216.14 | G15: =E15-F15 -> 1391.86 | H15: =G15*(1-TPCIL!$L$11)+F15 -> 1541.0515 | I15: =H15+X15 -> 1541.0515 | J15: =ISGS!V25 -> 493.75 | K15: =I15-J15 -> 1047.3015 | L15: =(TPCIL!I25-TPCIL!C25)+(TPCIL!P25-TPCIL!D25) -> 98.760545 | M15: =+L15+K15 -> 1146.0621 | O15: =IF(ISGS!G25-Entitlement!K19*(1-TPCIL!$L$11)<0,0,ISGS!G25-Entitlement!K19*(1-TPCIL!$L$11)) -> 0 | P15: =IF(ISGS!O25-Entitlement!AH19*(1-TPCIL!$L$11)<0,0,ISGS!O25-Entitlement!AH19*(1-TPCIL!$L$11)) -> 0 | Q15: =IF(ISGS!P25-Entitlement!AK19*(1-TPCIL!$L$11)<0,0,ISGS!P25-Entitlement!AK19*(1-TPCIL!$L$11)) -> 0 | R15: =IF(ISGS!U25-Entitlement!AZ19*(1-TPCIL!$L$11)<0,0,ISGS!U25-Entitlement!AZ19*(1-TPCIL!$L$11)) -> 0 | S15: =IF(ISGS!Q25-Entitlement!AN19<0,0,ISGS!Q25-Entitlement!AN19) -> 0 | T15: =IF(ISGS!R25-Entitlement!AQ19*(1-TPCIL!$L$11)<0,0,ISGS!R25-Entitlement!AQ19*(1-TPCIL!$L$11)) -> 0 | U15: =IF(ISGS!S25-Entitlement!AT19<0,0,ISGS!S25-Entitlement!AT19) -> 0 | V15: =IF(ISGS!K25-Entitlement!V19*(1-TPCIL!$L$11)<0,0,ISGS!K25-Entitlement!V19*(1-TPCIL!$L$11)) -> 0 | X15: =SUM(O15:W15) -> 0
... A98: 96 | B98: 23:45-24:00 | C98: =Entitlement!BC102 -> 1621.63 | D98: =(Entitlement!L102+Entitlement!Q102+Entitlement!T102+Entitlement!W102+Entitlement!Z102+Entitlement!AC102+Entitlement!AF102+Entitlement!AI102+Entitlement!AL102+Entitlement!AO102+Entitlement!AR102+Entitlement!AU102+Entitlement!AX102+Entitlement!BA102) -> 0 | E98: =C98-D98 -> 1621.63 | F98: =ISGS!Q108 -> 216.14 | G98: =E98-F98 -> 1405.49 | H98: =G98*(1-TPCIL!$L$11)+F98 -> 1554.0259 | I98: =H98+X98 -> 1554.0259 | J98: =ISGS!V108 -> 521.59 | K98: =I98-J98 -> 1032.4359 | L98: =(TPCIL!I108-TPCIL!C108)+(TPCIL!P108-TPCIL!D108) -> 0.000545 | M98: =+L98+K98 -> 1032.4365 | O98: =IF(ISGS!G108-Entitlement!K102*(1-TPCIL!$L$11)<0,0,ISGS!G108-Entitlement!K102*(1-TPCIL!$L$11)) -> 0 | P98: =IF(ISGS!O108-Entitlement!AH102*(1-TPCIL!$L$11)<0,0,ISGS!O108-Entitlement!AH102*(1-TPCIL!$L$11)) -> 0 | Q98: =IF(ISGS!P108-Entitlement!AK102*(1-TPCIL!$L$11)<0,0,ISGS!P108-Entitlement!AK102*(1-TPCIL!$L$11)) -> 0 | R98: =IF(ISGS!U108-Entitlement!AZ102*(1-TPCIL!$L$11)<0,0,ISGS!U108-Entitlement!AZ102*(1-TPCIL!$L$11)) -> 0 | S98: =IF(ISGS!Q108-Entitlement!AN102<0,0,ISGS!Q108-Entitlement!AN102) -> 0 | T98: =IF(ISGS!R108-Entitlement!AQ102*(1-TPCIL!$L$11)<0,0,ISGS!R108-Entitlement!AQ102*(1-TPCIL!$L$11)) -> 0 | U98: =IF(ISGS!S108-Entitlement!AT102<0,0,ISGS!S108-Entitlement!AT102) -> 0 | V98: =IF(ISGS!K108-Entitlement!V102*(1-TPCIL!$L$11)<0,0,ISGS!K108-Entitlement!V102*(1-TPCIL!$L$11)) -> 0 | X98: =SUM(O98:W98) -> 0
A99: TOTAL | B99: MU | C99: =AVERAGE(C3:C98)*24/1000 -> 38.940485 | D99: =AVERAGE(D3:D98)*24/1000 -> 0.11336 | E99: =AVERAGE(E3:E98)*24/1000 -> 38.827125 | F99: =AVERAGE(F3:F98)*24/1000 -> 5.18736 | G99: =AVERAGE(G3:G98)*24/1000 -> 33.639765 | H99: =AVERAGE(H3:H98)*24/1000 -> 37.209052 | I99: =AVERAGE(I3:I98)*24/1000 -> 37.209162 | J99: =AVERAGE(J3:J98)*24/1000 -> 28.43141 | ... M99: =AVERAGE(M3:M98)*24/1000 -> 9.0246653 | O99: =AVERAGE(O3:O98)*24/1000 -> 0 | P99: =AVERAGE(P3:P98)*24/1000 -> 6.222125e-05 | Q99: =AVERAGE(Q3:Q98)*24/1000 -> 0 | R99: =AVERAGE(R3:R98)*24/1000 -> 0 | S99: =AVERAGE(S3:S98)*24/1000 -> 0 | T99: =AVERAGE(T3:T98)*24/1000 -> 0 | U99: =AVERAGE(U3:U98)*24/1000 -> 0 | V99: =AVERAGE(V3:V98)*24/1000 -> 4.771075e-05 | ... X99: =AVERAGE(X3:X98)*24/1000 -> 0.000109932

Sheet Actual
A1: REPORT FOR APGENCO_THERMAL_individual_units FROM 1/12/2026 TO 1/13/2026
A2: Time | B2: VTSO2_AG.XFMR_P.20_G1.MW | C2: VTSO2_AG.XFMR_P.20_G2.MW | D2: VTSO2_AG.XFMR_P.20_G3.MW | E2: VTSO2_AG.XFMR_P.20_G4.MW | F2: VTSO2_AG.XFMR_P.20_G5.MW | G2: VTSO2_AG.XFMR_P.20_G6.MW | H2: VTS44_AG.XFMR_P.40_G1.MW | I2: RTPP2_AG.XFMR_P.20_G1.MW | J2: RTPP2_AG.XFMR_P.20_G2.MW | K2: RTPP2_AG.XFMR_P.20_G3.MW | L2: RTPP2_AG.XFMR_P.20_G4.MW | M2: RTPP2_AG.XFMR_P.20_G5.MW | N2: RTPP4_AG.XFMR_P.40_G1.MW | O2: KPTM4_AG.XFMR_P.40_G1.MW | P2: KPTM4_AG.XFMR_P.40_G2.MW | Q2: JGRP2_AG.STTN.X_BUS_GEN.MW | R2: JGRP2_AG.XFMR_P.20_G1.MW | S2: JGRP2_AG.XFMR_P.20_G2.MW | T2: JGRP2_AG.XFMR_P.20_G3.MW | U2: JGRP2_AG.XFMR_P.20_G4.MW | V2: KPTM4_AG.STTN.X_BUS_GEN.MW | W2: RTPP2_AG.STTN.X_BUS_GEN.MW | X2: RTPP4_AG.STTN.X_BUS_GEN.MW | Y2: VTS44_AG.STTN.X_BUS_GEN.MW | Z2: VTSO2_AG.STTN.X_BUS_GEN.MW | AA2: KPTM4_AG.XFMR_P.40_G3.MW | AB2: VTS54_AG.STTN.X_BUS_GEN.MW
