Workbook

Sheet New method
B2: Back down and Non compliance of HNPCL for Dec 2025
B3: Back down | J3: Non compliance
B4: Date | C4: From | D4: To | E4: DC (MW) | F4: As per SLDC Scada in MW | G4: Diff (MW) | H4: Mus | J4: MW as per ramp | K4: Diff | L4: MU
B5: 46023 | C5: 1.84375 | D5: 1.8541667 | E5: 492.7 | F5: 455.44 | G5: =E5-F5 -> 37.26 | H5: =G5/4000 -> 0.009315 | J5: =E5-40 -> 452.7 | K5: =F5-J5 -> 2.74
C6: 1.8541667 | D6: 1.8645833 | E6: 492.7 | F6: 409.35 | G6: =E6-F6 -> 83.35 | H6: =G6/4000 -> 0.0208375 | J6: =J5-40 -> 412.7 | K6: =F6-J6 -> -3.35 | L6: =IF(K6/4000>0,K6/4000,0) -> 0
C7: 1.8645833 | D7: 1.875 | E7: 492.7 | F7: 366.3 | G7: =E7-F7 -> 126.4 | H7: =G7/4000 -> 0.0316 | J7: =J6-40 -> 372.7 | K7: =F7-J7 -> -6.4 | L7: =IF(K7/4000>0,K7/4000,0) -> 0
C8: 1.875 | D8: 1.8854167 | E8: 492.7 | F8: 327.53 | G8: =E8-F8 -> 165.17 | H8: =G8/4000 -> 0.0412925 | J8: =J7-40 -> 332.7 | K8: =F8-J8 -> -5.17 | L8: =IF(K8/4000>0,K8/4000,0) -> 0
C9: 1.8854167 | D9: 1.8958333 | E9: 492.7 | F9: 293.39 | G9: =E9-F9 -> 199.31 | H9: =G9/4000 -> 0.0498275 | J9: =J8-40 -> 292.7 | K9: =F9-J9 -> 0.69 | L9: =IF(K9/4000>0,K9/4000,0) -> 0.0001725
C10: 1.8958333 | D10: 1.90625 | E10: 492.7 | F10: 267.05 | G10: =E10-F10 -> 225.65 | H10: =G10/4000 -> 0.0564125 | J10: 270 | K10: =F10-J10 -> -2.95 | L10: =IF(K10/4000>0,K10/4000,0) -> 0
C11: 1.90625 | D11: 1.9166667 | E11: 492.7 | F11: 268.22 | G11: =E11-F11 -> 224.48 | H11: =G11/4000 -> 0.05612 | J11: 270 | K11: =F11-J11 -> -1.78 | L11: =IF(K11/4000>0,K11/4000,0) -> 0
C12: 1.9166667 | D12: 1.9270833 | E12: 492.7 | F12: 268.95 | G12: =E12-F12 -> 223.75 | H12: =G12/4000 -> 0.0559375 | J12: 270 | K12: =F12-J12 -> -1.05 | L12: =IF(K12/4000>0,K12/4000,0) -> 0
C13: 1.9270833 | D13: 1.9375 | E13: 492.7 | F13: 271.08 | G13: =E13-F13 -> 221.62 | H13: =G13/4000 -> 0.055405 | J13: 270 | K13: =F13-J13 -> 1.08 | L13: =IF(K13/4000>0,K13/4000,0) -> 0.00027
C14: 1.9375 | D14: 1.9479167 | E14: 492.7 | F14: 270.75 | G14: =E14-F14 -> 221.95 | H14: =G14/4000 -> 0.0554875 | J14: 270 | K14: =F14-J14 -> 0.75 | L14: =IF(K14/4000>0,K14/4000,0) -> 0.0001875
C15: 1.9479167 | D15: 1.9583333 | E15: 492.7 | F15: 273.19 | G15: =E15-F15 -> 219.51 | H15: =G15/4000 -> 0.0548775 | J15: 270 | K15: =F15-J15 -> 3.19 | L15: =IF(K15/4000>0,K15/4000,0) -> 0.0007975
C16: 1.9583333 | D16: 1.96875 | E16: 492.7 | F16: 271.99 | G16: =E16-F16 -> 220.71 | H16: =G16/4000 -> 0.0551775 | J16: 270 | K16: =F16-J16 -> 1.99 | L16: =IF(K16/4000>0,K16/4000,0) -> 0.0004975
C17: 1.96875 | D17: 1.9791667 | E17: 492.7 | F17: 273.22 | G17: =E17-F17 -> 219.48 | H17: =G17/4000 -> 0.05487 | J17: 270 | K17: =F17-J17 -> 3.22 | L17: =IF(K17/4000>0,K17/4000,0) -> 0.000805
C18: 1.9791667 | D18: 1.9895833 | E18: 492.7 | F18: 270.73 | G18: =E18-F18 -> 221.97 | H18: =G18/4000 -> 0.0554925 | J18: 270 | K18: =F18-J18 -> 0.73 | L18: =IF(K18/4000>0,K18/4000,0) -> 0.0001825
C19: 1.9895833 | D19: 2 | E19: 492.7 | F19: 273.24 | G19: =E19-F19 -> 219.46 | H19: =G19/4000 -> 0.054865 | J19: 270 | K19: =F19-J19 -> 3.24 | L19: =IF(K19/4000>0,K19/4000,0) -> 0.00081
I20: =SUM(H5:H19) -> 0.7075175 | M20: =SUM(L5:L19) -> 0.0037225
B21: 46024 | C21: 1 | D21: 1.0104167 | E21: 492.7 | F21: 273.94 | G21: =E21-F21 -> 218.76 | H21: =G21/4000 -> 0.05469 | J21: 270 | K21: =F21-J21 -> 3.94
C22: 1.0104167 | D22: 1.0208333 | E22: 492.7 | F22: 274.13 | G22: =E22-F22 -> 218.57 | H22: =G22/4000 -> 0.0546425 | J22: 270 | K22: =F22-J22 -> 4.13 | L22: =IF(K22/4000>0,K22/4000,0) -> 0.0010325
C23: 1.0208333 | D23: 1.03125 | E23: 492.7 | F23: 319.4 | G23: =E23-F23 -> 173.3 | H23: =G23/4000 -> 0.043325 | J23: =J22+40 -> 310 | K23: =J23-F23 -> -9.4 | L23: =IF(K23/4000>0,K23/4000,0) -> 0
C24: 1.03125 | D24: 1.0416667 | E24: 492.7 | F24: 420.71 | G24: =E24-F24 -> 71.99 | H24: =G24/4000 -> 0.0179975 | J24: =J23+40 -> 350 | K24: =J24-F24 -> -70.71 | L24: =IF(K24/4000>0,K24/4000,0) -> 0
C25: 1.0416667 | D25: 1.0520833 | E25: 492.7 | F25: 488.23 | G25: =E25-F25 -> 4.47 | H25: =G25/4000 -> 0.0011175 | J25: =J24+40 -> 390 | K25: =J25-F25 -> -98.23 | L25: =IF(K25/4000>0,K25/4000,0) -> 0
C26: 1.0520833 | D26: 1.0625 | E26: 492.7 | F26: 488.54 | G26: =E26-F26 -> 4.16 | H26: =G26/4000 -> 0.00104 | J26: =J25+40 -> 430 | K26: =J26-F26 -> -58.54 | L26: =IF(K26/4000>0,K26/4000,0) -> 0
C27: 1.0625 | D27: 1.0729167 | E27: 492.7 | F27: 493.7 | G27: =E27-F27 -> -1 | H27: 0 | J27: =J26+40 -> 470 | K27: =J27-F27 -> -23.7 | L27: =IF(K27/4000>0,K27/4000,0) -> 0
I28: =SUM(H21:H27) -> 0.1728125 | M28: =SUM(L21:L27) -> 0.0010325
B29: 46024 | C29: 1.0729167 | D29: 1.0833333 | E29: 492.7 | F29: 434.02 | G29: =E29-F29 -> 58.68 | H29: =G29/4000 -> 0.01467 | J29: =J27-40 -> 430 | K29: =F29-J29 -> 4.02
C30: 1.0833333 | D30: 1.09375 | E30: 492.7 | F30: 357.66 | G30: =E30-F30 -> 135.04 | H30: =G30/4000 -> 0.03376 | J30: =J29-40 -> 390 | K30: =F30-J30 -> -32.34 | L30: =IF(K30/4000>0,K30/4000,0) -> 0
C31: 1.09375 | D31: 1.1041667 | E31: 492.7 | F31: 290.37 | G31: =E31-F31 -> 202.33 | H31: =G31/4000 -> 0.0505825 | J31: =J30-40 -> 350 | K31: =F31-J31 -> -59.63 | L31: =IF(K31/4000>0,K31/4000,0) -> 0
C32: 1.1041667 | D32: 1.1145833 | E32: 492.7 | F32: 268.99 | G32: =E32-F32 -> 223.71 | H32: =G32/4000 -> 0.0559275 | J32: =J31-40 -> 310 | K32: =F32-J32 -> -41.01 | L32: =IF(K32/4000>0,K32/4000,0) -> 0
C33: 1.1145833 | D33: 1.125 | E33: 492.7 | F33: 267.7 | G33: =E33-F33 -> 225 | H33: =G33/4000 -> 0.05625 | J33: =J32-40 -> 270 | K33: =F33-J33 -> -2.3 | L33: =IF(K33/4000>0,K33/4000,0) -> 0
C34: 1.125 | D34: 1.1354167 | E34: 492.7 | F34: 341.14 | G34: =E34-F34 -> 151.56 | H34: =G34/4000 -> 0.03789 | J34: =J33+40 -> 310 | K34: =J34-F34 -> -31.14 | L34: =IF(K34/4000>0,K34/4000,0) -> 0
C35: 1.1354167 | D35: 1.1458333 | E35: 492.7 | F35: 436.14 | G35: =E35-F35 -> 56.56 | H35: =G35/4000 -> 0.01414 | J35: =J34+40 -> 350 | K35: =J35-F35 -> -86.14 | L35: =IF(K35/4000>0,K35/4000,0) -> 0
C36: 1.1458333 | D36: 1.15625 | E36: 492.7 | F36: 484.78 | G36: =E36-F36 -> 7.92 | H36: =G36/4000 -> 0.00198 | J36: =J35+40 -> 390 | K36: =J36-F36 -> -94.78 | L36: =IF(K36/4000>0,K36/4000,0) -> 0
C37: 1.15625 | D37: 1.1666667 | E37: 492.7 | F37: 489.86 | G37: =E37-F37 -> 2.84 | H37: =G37/4000 -> 0.00071 | J37: =J36+40 -> 430 | K37: =J37-F37 -> -59.86 | L37: =IF(K37/4000>0,K37/4000,0) -> 0
C38: 1.1666667 | D38: 1.1770833 | E38: 492.7 | F38: 492.26 | G38: =E38-F38 -> 0.44 | H38: =G38/4000 -> 0.00011 | J38: =J37+40 -> 470 | K38: =J38-F38 -> -22.26 | L38: =IF(K38/4000>0,K38/4000,0) -> 0
I39: =SUM(H29:H38) -> 0.26602 | M39: =SUM(L29:L38) -> 0
B40: 46024 | C40: 1.9166667 | D40: 1.9270833 | E40: 492.7 | F40: 469.03 | G40: =E40-F40 -> 23.67 | H40: =G40/4000 -> 0.0059175 | J40: =E40-40 -> 452.7 | K40: =F40-J40 -> 16.33
C41: 1.9270833 | D41: 1.9375 | E41: 492.7 | F41: 412.5 | G41: =E41-F41 -> 80.2 | H41: =G41/4000 -> 0.02005 | J41: =J40-40 -> 412.7 | K41: =F41-J41 -> -0.2 | L41: =IF(K41/4000>0,K41/4000,0) -> 0
...

Sheet Sheet1
G2: ABSTRACT of Backing down details of HNPCL for the month of JAN 2026
G3: Date | H3: Backing down in MU | I3: Non compliance in MU | K3: 5 minutes average | L3: 10 minutes average | M3: 15 minutes average
B4: 1 | C4: 1.0104167 | G4: 45992 | H4: ='New method'!I20 -> 0.7075175 | I4: ='New method'!M20 -> 0.0037225 | K4: 5 | L4: 5 | M4: 5
B5: 1.0104167 | C5: 1.0208333 | G5: 45993 | H5: ='New method'!I28+'New method'!I39+'New method'!I48 -> 0.77736 | I5: ='New method'!M28+'New method'!M39+'New method'!M48 -> 0.0017075 | K5: 10 | L5: 10 | M5: 10
B6: 1.0208333 | C6: 1.03125 | G6: 45994 | H6: ='New method'!I68+'New method'!I87+'New method'!I92+'New method'!I101 -> 1.889435 | I6: ='New method'!M68+'New method'!M87+'New method'!M92+'New method'!M101 -> 0.023165 | K6: 15 | L6: 15 | M6: 15
B7: 1.03125 | C7: 1.0416667 | G7: 45995 | H7: ='New method'!I119+'New method'!I126+'New method'!I137+'New method'!I147 -> 1.5015725 | I7: ='New method'!M119+'New method'!M126+'New method'!M137+'New method'!M147 -> 0.065185 | K7: 20 | L7: 20 | M7: 20
B8: 1.0416667 | C8: 1.0520833 | G8: 45996 | H8: ='New method'!I168+'New method'!I177+'New method'!I187 -> 1.4331575 | I8: ='New method'!M168+'New method'!M177+'New method'!M187 -> 0.063075 | K8: 25 | L8: 25 | M8: 25
B9: 1.0520833 | C9: 1.0625 | G9: 45997 | H9: ='New method'!I201+'New method'!I216+'New method'!I222 -> 1.1164975 | I9: ='New method'!M201+'New method'!M216+'New method'!M222 -> 0.1393325 | J9: for 1 unit | K9: =AVERAGE(K4:K8) -> 15 | L9: 30 | M9: 30
B10: 1.0625 | C10: 1.0729167 | G10: 45998 | H10: ='New method'!I245+'New method'!I257+'New method'!I272 -> 1.651415 | I10: ='New method'!M245+'New method'!M257+'New method'!M272 -> 0.0411975 | J10: for 2 units | K10: 30 | L10: 35 | M10: 35
B11: 1.0729167 | C11: 1.0833333 | G11: 45999 | H11: ='New method'!I300+'New method'!I310 -> 1.6416375 | I11: ='New method'!M300+'New method'!M310 -> 0.0860825 | L11: 40 | M11: 40
B12: 1.0833333 | C12: 1.09375 | G12: 46000 | H12: ='New method'!I334+'New method'!I339 -> 1.173875 | I12: ='New method'!M334+'New method'!M339 -> 0.0765425 | L12: 45 | M12: 45
B13: 1.09375 | C13: 1.1041667 | G13: 46001 | H13: ='New method'!I363+'New method'!I368+'New method'!I381 -> 1.68533 | I13: ='New method'!M363+'New method'!M368+'New method'!M381 -> 0.1134425 | L13: 50 | M13: 50
B14: 1.1041667 | C14: 1.1145833 | G14: 46002 | H14: ='New method'!I404+'New method'!I417+'New method'!I425 -> 1.776955 | I14: ='New method'!M404+'New method'!M417+'New method'!M425 -> 0.06691 | K14: for 1 unit | L14: =AVERAGE(L4:L13) -> 27.5 | M14: 55
B15: 1.1145833 | C15: 1.125 | G15: 46003 | H15: ='New method'!I450+'New method'!I456 -> 1.3098775 | I15: ='New method'!M450+'New method'!M456 -> 0.0341475 | K15: for 2 units | L15: 55 | M15: 60
B16: 1.125 | C16: 1.1354167 | G16: 46004 | H16: ='New method'!I480+'New method'!I489+'New method'!I492 -> 1.3185075 | I16: ='New method'!M480+'New method'!M489+'New method'!M492 -> 0.0472575 | M16: 65
B17: 1.1354167 | C17: 1.1458333 | G17: 46005 | H17: ='New method'!I515+'New method'!I532+'New method'!I540+'New method'!I545 -> 1.926235 | I17: ='New method'!M515+'New method'!M532+'New method'!M540+'New method'!M545 -> 0.184825 | M17: 70
B18: 1.1458333 | C18: 1.15625 | G18: 46006 | H18: ='New method'!I569+'New method'!I604+'New method'!I618 -> 3.0006275 | I18: ='New method'!M569+'New method'!M604+'New method'!M618 -> 0.3090725 | M18: 75
B19: 1.15625 | C19: 1.1666667 | G19: 46007 | H19: ='New method'!I642+'New method'!I668+'New method'!I676+'New method'!I682 -> 2.5175475 | I19: ='New method'!M642+'New method'!M668+'New method'!M676+'New method'!M682 -> 0.10003 | L19: for 1 unit | M19: =AVERAGE(M4:M18) -> 40
B20: 1.1666667 | C20: 1.1770833 | G20: 46008 | H20: ='New method'!I706+'New method'!I723+'New method'!I734 -> 2.1844225 | I20: ='New method'!M706+'New method'!M723+'New method'!M734 -> 0.10096 | L20: for 2 units | M20: 80
B21: 1.1770833 | C21: 1.1875 | G21: 46009 | H21: ='New method'!I739+'New method'!I760+'New method'!I787+'New method'!I802 -> 2.712855 | I21: ='New method'!M739+'New method'!M760+'New method'!M787+'New method'!M802 -> 0.155815
B22: 1.1875 | C22: 1.1979167 | G22: 46010 | H22: ='New method'!I820+'New method'!I833+'New method'!I848 -> 1.8468225 | I22: ='New method'!M820+'New method'!M833+'New method'!M848 -> 0.07654
B23: 1.1979167 | C23: 1.2083333 | G23: 46011 | H23: ='New method'!I868+'New method'!I882+'New method'!I899 -> 2.1295425 | I23: ='New method'!M868+'New method'!M882+'New method'!M899 -> 0.06852
B24: 1.2083333 | C24: 1.21875 | G24: 46012 | H24: ='New method'!I923+'New method'!I945+'New method'!I958 -> 2.557125 | I24: ='New method'!M923+'New method'!M945+'New method'!M958 -> 0.059725
B25: 1.21875 | C25: 1.2291667 | G25: 46013 | H25: ='New method'!I983+'New method'!I995+'New method'!I1001+'New method'!I1017 -> 2.93131 | I25: ='New method'!M983+'New method'!M995+'New method'!M1001+'New method'!M1017 -> 0.100375
B26: 1.2291667 | C26: 1.2395833 | G26: 46014 | H26: ='New method'!I1048+'New method'!I1083+'New method'!I1101 -> 5.5174175 | I26: ='New method'!M1048+'New method'!M1083+'New method'!M1101 -> 0.086425
B27: 1.2395833 | C27: 1.25 | G27: 46015 | H27: ='New method'!I1127+'New method'!I1138+'New method'!I1143+'New method'!I1147+'New method'!I1148+'New method'!I1155+'New method'!I1158+'New method'!I1163 -> 3.377925 | I27: ='New method'!M1127+'New method'!M1138+'New method'!M1143+'New method'!M1147+'New method'!M1148+'New method'!M1155+'New method'!M1158+'New method'!M1163 -> 0.031285
B28: 1.25 | C28: 1.2604167 | G28: 46016 | H28: ='New method'!I1194+'New method'!I1250 -> 7.1033387 | I28: ='New method'!M1194+'New method'!M1250 -> 0.07008375
B29: 1.2604167 | C29: 1.2708333 | G29: 46017 | H29: ='New method'!I1276+'New method'!I1321 -> 5.667685 | I29: ='New method'!M1276+'New method'!M1321 -> 0.0676125
B30: 1.2708333 | C30: 1.28125 | G30: 46018 | H30: ='New method'!I1352+'New method'!I1375+'New method'!I1393 -> 5.2207775 | I30: ='New method'!M1352+'New method'!M1375+'New method'!M1393 -> 0.0619275
B31: 1.28125 | C31: 1.2916667 | G31: 46019 | H31: ='New method'!I1423+'New method'!I1441+'New method'!I1451+'New method'!I1467 -> 5.7240775 | I31: ='New method'!M1423+'New method'!M1441+'New method'!M1451+'New method'!M1467 -> 0.05602
B32: 1.2916667 | C32: 1.3020833 | G32: 46020 | H32: ='New method'!I1495+'New method'!I1523+'New method'!I1540 -> 6.4082625 | I32: ='New method'!M1495+'New method'!M1523+'New method'!M1540 -> 0.15173
B33: 1.3020833 | C33: 1.3125 | G33: 46021 | H33: ='New method'!I1570+'New method'!I1575+'New method'!I1583+'New method'!I1598+'New method'!I1615 -> 6.968565 | I33: ='New method'!M1570+'New method'!M1575+'New method'!M1583+'New method'!M1598+'New method'!M1615 -> 0.0732075
B34: 1.3125 | C34: 1.3229167 | G34: 46022 | H34: ='New method'!I1644+'New method'!I1675+'New method'!I1692 -> 6.8601075 | I34: ='New method'!M1644+'New method'!M1675+'New method'!M1692 -> 0.089975
B35: 1.3229167 | C35: 1.3333333 | G35: Total | H35: =SUM(H4:H34) -> 92.637781 | I35: =SUM(I4:I34) -> 2.6058963
B36: 1.3333333 | C36: 1.34375
B37: 1.34375 | C37: 1.3541667
B38: 1.3541667 | C38: 1.3645833
B39: 1.3645833 | C39: 1.375
B40: 1.375 | C40: 1.3854167
B41: 1.3854167 | C41: 1.3958333
...

Sheet Sheet2
B3: For 600 MW units | H3: For 500 MW units | L3: For 800 MW units | Q3: For 210 MW units
C4: =C3+6 -> 6 | D4: =D3+6 -> 6 | E4: =E3+6 -> 6 | H4: 5 minutes average | I4: 10 minutes average | J4: 15 minutes average | M4: =M3+8 -> 8 | N4: =N3+8 -> 8 | O4: =O3+8 -> 8 | R4: =R3+2.1 -> 2.1 | S4: =S3+2.1 -> 2.1 | T4: =T3+2.1 -> 2.1
C5: =C4+6 -> 12 | D5: =D4+6 -> 12 | E5: =E4+6 -> 12 | H5: 5 | I5: 5 | J5: 5 | M5: =M4+8 -> 16 | N5: =N4+8 -> 16 | O5: =O4+8 -> 16 | R5: =R4+2.1 -> 4.2 | S5: =S4+2.1 -> 4.2 | T5: =T4+2.1 -> 4.2
C6: =C5+6 -> 18 | D6: =D5+6 -> 18 | E6: =E5+6 -> 18 | H6: 10 | I6: 10 | J6: 10 | M6: =M5+8 -> 24 | N6: =N5+8 -> 24 | O6: =O5+8 -> 24 | R6: =R5+2.1 -> 6.3 | S6: =S5+2.1 -> 6.3 | T6: =T5+2.1 -> 6.3
C7: =C6+6 -> 24 | D7: =D6+6 -> 24 | E7: =E6+6 -> 24 | H7: 15 | I7: 15 | J7: 15 | M7: =M6+8 -> 32 | N7: =N6+8 -> 32 | O7: =O6+8 -> 32 | R7: =R6+2.1 -> 8.4 | S7: =S6+2.1 -> 8.4 | T7: =T6+2.1 -> 8.4
C8: =C7+6 -> 30 | D8: =D7+6 -> 30 | E8: =E7+6 -> 30 | H8: 20 | I8: 20 | J8: 20 | M8: =M7+8 -> 40 | N8: =N7+8 -> 40 | O8: =O7+8 -> 40 | R8: =R7+2.1 -> 10.5 | S8: =S7+2.1 -> 10.5 | T8: =T7+2.1 -> 10.5
B9: for 1 unit | C9: =AVERAGE(C4:C8) -> 18 | D9: =D8+6 -> 36 | E9: =E8+6 -> 36 | H9: 25 | I9: 25 | J9: 25 | L9: for 1 unit | M9: =AVERAGE(M4:M8) -> 24 | N9: =N8+8 -> 48 | O9: =O8+8 -> 48 | Q9: for 1 unit | R9: =AVERAGE(R4:R8) -> 6.3 | S9: =S8+2.1 -> 12.6 | T9: =T8+2.1 -> 12.6
D10: =D9+6 -> 42 | E10: =E9+6 -> 42 | G10: for 1 unit | H10: =AVERAGE(H5:H9) -> 15 | I10: 30 | J10: 30 | N10: =N9+8 -> 56 | O10: =O9+8 -> 56 | Q10: for 2 units | R10: 12.6 | S10: =S9+2.1 -> 14.7 | T10: =T9+2.1 -> 14.7
D11: =D10+6 -> 48 | E11: =E10+6 -> 48 | G11: for 2 units | H11: 30 | I11: 35 | J11: 35 | N11: =N10+8 -> 64 | O11: =O10+8 -> 64 | S11: =S10+2.1 -> 16.8 | T11: =T10+2.1 -> 16.8
D12: =D11+6 -> 54 | E12: =E11+6 -> 54 | I12: 40 | J12: 40 | N12: =N11+8 -> 72 | O12: =O11+8 -> 72 | S12: =S11+2.1 -> 18.9 | T12: =T11+2.1 -> 18.9
D13: =D12+6 -> 60 | E13: =E12+6 -> 60 | I13: 45 | J13: 45 | N13: =N12+8 -> 80 | O13: =O12+8 -> 80 | S13: =S12+2.1 -> 21 | T13: =T12+2.1 -> 21
C14: for 1 unit | D14: 33 | E14: =E13+6 -> 66 | I14: 50 | J14: 50 | M14: for 1 unit | N14: 44 | O14: =O13+8 -> 88 | R14: for 1 unit | S14: 11.55 | T14: =T13+2.1 -> 23.1
E15: =E14+6 -> 72 | H15: for 1 unit | I15: =AVERAGE(I5:I14) -> 27.5 | J15: 55 | O15: =O14+8 -> 96 | R15: for 2 units | S15: 23.1 | T15: =T14+2.1 -> 25.2
E16: =E15+6 -> 78 | H16: for 2 units | I16: 55 | J16: 60 | O16: =O15+8 -> 104 | T16: =T15+2.1 -> 27.3
E17: =E16+6 -> 84 | J17: 65 | O17: =O16+8 -> 112 | T17: =T16+2.1 -> 29.4
E18: =E17+6 -> 90 | J18: 70 | O18: =O17+8 -> 120 | T18: =T17+2.1 -> 31.5
E19: =E18+6 -> 96 | J19: 75 | O19: =O18+6 -> 126 | T19: =T18+2.1 -> 33.6
D20: for 1 unit | E20: 17.85 | I20: for 1 unit | J20: =AVERAGE(J5:J19) -> 40 | N20: for 1 unit | O20: 67.875 | S20: for 1 unit | T20: 17.85
I21: for 2 units | J21: 80 | S21: for 2 units | T21: 35.7
