Workbook

Sheet Sheet2
B3: For 600 MW units | H3: For 500 MW units | L3: For 800 MW units | Q3: For 210 MW units
C4: =C3+6 -> 6 | D4: =D3+6 -> 6 | E4: =E3+6 -> 6 | H4: 5 minutes average | I4: 10 minutes average | J4: 15 minutes average | M4: =M3+8 -> 8 | N4: =N3+8 -> 8 | O4: =O3+8 -> 8 | R4: =R3+2.1 -> 2.1 | S4: =S3+2.1 -> 2.1 | T4: =T3+2.1 -> 2.1
C5: =C4+6 -> 12 | D5: =D4+6 -> 12 | E5: =E4+6 -> 12 | H5: 5 | I5: 5 | J5: 5 | M5: =M4+8 -> 16 | N5: =N4+8 -> 16 | O5: =O4+8 -> 16 | R5: =R4+2.1 -> 4.2 | S5: =S4+2.1 -> 4.2 | T5: =T4+2.1 -> 4.2
C6: =C5+6 -> 18 | D6: =D5+6 -> 18 | E6: =E5+6 -> 18 | H6: 10 | I6: 10 | J6: 10 | M6: =M5+8 -> 24 | N6: =N5+8 -> 24 | O6: =O5+8 -> 24 | R6: =R5+2.1 -> 6.3 | S6: =S5+2.1 -> 6.3 | T6: =T5+2.1 -> 6.3
C7: =C6+6 -> 24 | D7: =D6+6 -> 24 | E7: =E6+6 -> 24 | H7: 15 | I7: 15 | J7: 15 | M7: =M6+8 -> 32 | N7: =N6+8 -> 32 | O7: =O6+8 -> 32 | R7: =R6+2.1 -> 8.4 | S7: =S6+2.1 -> 8.4 | T7: =T6+2.1 -> 8.4
C8: =C7+6 -> 30 | D8: =D7+6 -> 30 | E8: =E7+6 -> 30 | H8: 20 | I8: 20 | J8: 20 | M8: =M7+8 -> 40 | N8: =N7+8 -> 40 | O8: =O7+8 -> 40 | R8: =R7+2.1 -> 10.5 | S8: =S7+2.1 -> 10.5 | T8: =T7+2.1 -> 10.5
B9: for 1 unit | C9: =AVERAGE(C4:C8) -> 18 | D9: =D8+6 -> 36 | E9: =E8+6 -> 36 | H9: 25 | I9: 25 | J9: 25 | L9: for 1 unit | M9: =AVERAGE(M4:M8) -> 24 | N9: =N8+8 -> 48 | O9: =O8+8 -> 48 | Q9: for 1 unit | R9: =AVERAGE(R4:R8) -> 6.3 | S9: =S8+2.1 -> 12.6 | T9: =T8+2.1 -> 12.6
D10: =D9+6 -> 42 | E10: =E9+6 -> 42 | H10: =AVERAGE(H5:H9) -> 15 | I10: 30 | J10: 30 | N10: =N9+8 -> 56 | O10: =O9+8 -> 56 | Q10: for 2 units | R10: 12.6 | S10: =S9+2.1 -> 14.7 | T10: =T9+2.1 -> 14.7
D11: =D10+6 -> 48 | E11: =E10+6 -> 48 | H11: 30 | I11: 35 | J11: 35 | N11: =N10+8 -> 64 | O11: =O10+8 -> 64 | S11: =S10+2.1 -> 16.8 | T11: =T10+2.1 -> 16.8
D12: =D11+6 -> 54 | E12: =E11+6 -> 54 | I12: 40 | J12: 40 | N12: =N11+8 -> 72 | O12: =O11+8 -> 72 | S12: =S11+2.1 -> 18.9 | T12: =T11+2.1 -> 18.9
D13: =D12+6 -> 60 | E13: =E12+6 -> 60 | I13: 45 | J13: 45 | N13: =N12+8 -> 80 | O13: =O12+8 -> 80 | S13: =S12+2.1 -> 21 | T13: =T12+2.1 -> 21
C14: for 1 unit | D14: 33 | E14: =E13+6 -> 66 | I14: 50 | J14: 50 | M14: for 1 unit | N14: 44 | O14: =O13+8 -> 88 | R14: for 1 unit | S14: 11.55 | T14: =T13+2.1 -> 23.1
E15: =E14+6 -> 72 | H15: for 1 unit | I15: =AVERAGE(I5:I14) -> 27.5 | J15: 55 | O15: =O14+8 -> 96 | R15: for 2 units | S15: 23.1 | T15: =T14+2.1 -> 25.2
E16: =E15+6 -> 78 | H16: for 2 units | I16: 55 | J16: 60 | O16: =O15+8 -> 104 | T16: =T15+2.1 -> 27.3
E17: =E16+6 -> 84 | J17: 65 | O17: =O16+8 -> 112 | T17: =T16+2.1 -> 29.4
E18: =E17+6 -> 90 | J18: 70 | O18: =O17+8 -> 120 | T18: =T17+2.1 -> 31.5
E19: =E18+6 -> 96 | J19: 75 | O19: =O18+6 -> 126 | T19: =T18+2.1 -> 33.6
D20: for 1 unit | E20: 17.85 | I20: for 1 unit | J20: =AVERAGE(J5:J19) -> 40 | N20: for 1 unit | O20: 67.875 | S20: for 1 unit | T20: 17.85
I21: for 2 units | J21: 80 | S21: for 2 units | T21: 35.7

Sheet New method (2)
B2: Back down and Non compliance of HNPCL for Oct 2025
B3: Back down | J3: Non compliance
B4: Date | C4: From | D4: To | E4: DC (MW) | F4: As per SLDC Scada in MW | G4: Diff (MW) | H4: Mus | J4: MW as per ramp | K4: Diff | L4: MU
B5: 45932 | C5: 1.1041667 | D5: 1.1145833 | E5: 315 | F5: 280.54703 | G5: =E5-F5 -> 34.452968 | H5: =G5/4000 -> 0.0086132419 | J5: =E5-40 -> 275 | K5: =F5-J5 -> 5.5470324
C6: 1.1145833 | D6: 1.125 | E6: 375 | F6: 282.42583 | G6: =E6-F6 -> 92.574167 | H6: =G6/4000 -> 0.023143542 | J6: 270 | K6: =F6-J6 -> 12.425833 | L6: 0
C7: 1.125 | D7: 1.1354167 | E7: 440 | F7: 272.80016 | G7: =E7-F7 -> 167.19984 | H7: =G7/4000 -> 0.041799959 | J7: 270 | K7: =F7-J7 -> 2.8001637 | L7: =K7/4000 -> 0.00070004092
C8: 1.1354167 | D8: 1.1458333 | E8: 440 | F8: 270.68797 | G8: =E8-F8 -> 169.31203 | H8: =G8/4000 -> 0.042328007 | J8: 270 | K8: =F8-J8 -> 0.68797048 | L8: =K8/4000 -> 0.00017199262
C9: 1.1458333 | D9: 1.15625 | E9: 440 | F9: 269.25482 | G9: =E9-F9 -> 170.74518 | H9: =G9/4000 -> 0.042686295 | J9: 270 | K9: =F9-J9 -> -0.74517988 | L9: =K9/4000 -> -0.00018629497
C10: 1.15625 | D10: 1.1666667 | E10: 440 | F10: 269.2838 | G10: =E10-F10 -> 170.7162 | H10: =G10/4000 -> 0.042679051 | J10: 270 | K10: =F10-J10 -> -0.71620256 | L10: =K10/4000 -> -0.00017905064
C11: 1.1666667 | D11: 1.1770833 | E11: 440 | F11: 270.11951 | G11: =E11-F11 -> 169.88049 | H11: =G11/4000 -> 0.042470123 | J11: 270 | K11: =F11-J11 -> 0.11950762 | L11: =K11/4000 -> 2.9876904e-05
C12: 1.1770833 | D12: 1.1875 | E12: 440 | F12: 269.84894 | G12: =E12-F12 -> 170.15106 | H12: =G12/4000 -> 0.042537765 | J12: 270 | K12: =F12-J12 -> -0.15105808 | L12: =K12/4000 -> -3.776452e-05
C13: 1.1875 | D13: 1.1979167 | E13: 440 | F13: 269.08654 | G13: =E13-F13 -> 170.91346 | H13: =G13/4000 -> 0.042728365 | J13: 270 | K13: =F13-J13 -> -0.91346181 | L13: =K13/4000 -> -0.00022836545
C14: 1.1979167 | D14: 1.2083333 | E14: 440 | F14: 269.27543 | G14: =E14-F14 -> 170.72457 | H14: =G14/4000 -> 0.042681142 | J14: 270 | K14: =F14-J14 -> -0.72456787 | L14: =K14/4000 -> -0.00018114197
C15: 1.2083333 | D15: 1.21875 | E15: 440 | F15: 269.65879 | G15: =E15-F15 -> 170.34121 | H15: =G15/4000 -> 0.042585303 | J15: 270 | K15: =F15-J15 -> -0.34121029 | L15: =K15/4000 -> -8.5302573e-05
C16: 1.21875 | D16: 1.2291667 | E16: 440 | F16: 271.8937 | G16: =E16-F16 -> 168.1063 | H16: =G16/4000 -> 0.042026576 | J16: 270 | K16: =F16-J16 -> 1.8936953 | L16: =K16/4000 -> 0.00047342383
C17: 1.2291667 | D17: 1.2395833 | E17: 440 | F17: 271.21135 | G17: =E17-F17 -> 168.78865 | H17: =G17/4000 -> 0.042197163 | J17: 270 | K17: =F17-J17 -> 1.2113477 | L17: =K17/4000 -> 0.00030283692
C18: 1.2395833 | D18: 1.25 | E18: 440 | F18: 270.49838 | G18: =E18-F18 -> 169.50162 | H18: =G18/4000 -> 0.042375405 | J18: 270 | K18: =F18-J18 -> 0.49837992 | L18: =K18/4000 -> 0.00012459498
... C65: 1.7291667 | D65: 1.7395833 | E65: 440 | F65: 270.87984 | G65: =E65-F65 -> 169.12016 | H65: =G65/4000 -> 0.042280039 | J65: 270 | K65: =F65-J65 -> 0.87984338 | L65: =K65/4000 -> 0.00021996084
C66: 1.7395833 | D66: 1.75 | E66: 440 | F66: 272.66573 | G66: =E66-F66 -> 167.33427 | H66: =G66/4000 -> 0.041833567 | J66: 270 | K66: =F66-J66 -> 2.6657321 | L66: =K66/4000 -> 0.00066643303 | O66: =J66-J67 -> -40 | P66: =F66-F67 -> -29.336954
C67: 1.75 | D67: 1.7604167 | E67: 440 | F67: 302.00269 | G67: =E67-F67 -> 137.99731 | H67: =G67/4000 -> 0.034499328 | J67: =J66+40 -> 310 | K67: =F67-J67 -> -7.9973139 | L67: =K67/4000 -> -0.0019993285 | O67: =J67-J68 -> -40 | P67: =F67-F68 -> -70.344853
C68: 1.7604167 | D68: 1.7708333 | E68: 440 | F68: 372.34754 | G68: =E68-F68 -> 67.652461 | H68: =G68/4000 -> 0.016913115 | J68: =J67+40 -> 350 | K68: =F68-J68 -> 22.347539 | L68: =K68/4000 -> 0.0055868848 | O68: =J68-J69 -> -40 | P68: =F68-F69 -> -48.36584
C69: 1.7708333 | D69: 1.78125 | E69: 440 | F69: 420.71338 | G69: =E69-F69 -> 19.286621 | H69: =G69/4000 -> 0.0048216552 | J69: =J68+40 -> 390 | K69: =F69-J69 -> 30.713379 | L69: =K69/4000 -> 0.0076783448 | O69: =J69-J70 -> -40 | P69: =F69-F70 -> -1.3347664
C70: 1.7708333 | D70: 1.78125 | E70: 440 | F70: 422.04815 | G70: =E70-F70 -> 17.951855 | H70: =G70/4000 -> 0.0044879637 | J70: =J69+40 -> 430 | K70: =F70-J70 -> -7.9518546 | L70: =K70/4000 -> -0.0019879637 | O70: =J70-J71 -> 430 | P70: =F70-F71 -> 422.04815
I71: =SUM(H5:H70) -> 2.6456554 | M71: =SUM(L5:L70) -> 0.006101398
B72: 45932 | C72: 1.7916667 | D72: 1.8020833 | E72: 440 | F72: 418.50212 | G72: =E72-F72 -> 21.497882 | H72: =G72/4000 -> 0.0053744705 | J72: =E72-15 -> 425 | K72: =F72-J72 -> -6.497882 | O72: =E72-J72 -> 15 | P72: =E72-F72 -> 21.497882
C73: 1.8020833 | D73: 1.8125 | E73: 440 | F73: 353.24232 | G73: =E73-F73 -> 86.757683 | H73: =G73/4000 -> 0.021689421 | J73: =J72-40 -> 385 | K73: =F73-J73 -> -31.757683 | L73: =K73/4000 -> -0.0079394208 | O73: =J72-J73 -> 40 | P73: =F72-F73 -> 65.259801
C74: 1.8125 | D74: 1.8229167 | E74: 440 | F74: 291.03827 | G74: =E74-F74 -> 148.96173 | H74: =G74/4000 -> 0.037240433 | J74: =J73-40 -> 345 | K74: =F74-J74 -> -53.961732 | L74: =K74/4000 -> -0.013490433 | O74: =J73-J74 -> 40 | P74: =F73-F74 -> 62.204049
C75: 1.8229167 | D75: 1.8333333 | E75: 440 | F75: 273.47794 | G75: =E75-F75 -> 166.52206 | H75: =G75/4000 -> 0.041630515 | J75: =J74-40 -> 305 | K75: =F75-J75 -> -31.522061 | L75: =K75/4000 -> -0.0078805154 | O75: =J74-J75 -> 40 | P75: =F74-F75 -> 17.56033
C76: 1.8333333 | D76: 1.84375 | E76: 440 | F76: 272.39638 | G76: =E76-F76 -> 167.60362 | H76: =G76/4000 -> 0.041900904 | J76: 270 | K76: =F76-J76 -> 2.3963823 | L76: =K76/4000 -> 0.00059909557 | O76: =J75-J76 -> 35 | P76: =F75-F76 -> 1.0815563
C77: 1.84375 | D77: 1.8541667 | E77: 440 | F77: 271.42459 | G77: =E77-F77 -> 168.57541 | H77: =G77/4000 -> 0.042143853 | J77: 270 | K77: =F77-J77 -> 1.4245868 | L77: =K77/4000 -> 0.00035614669 | O77: =J76-J77 -> 0 | P77: =F76-F77 -> 0.97179552
C78: 1.8541667 | D78: 1.8645833 | E78: 440 | F78: 282.85987 | G78: =E78-F78 -> 157.14013 | H78: =G78/4000 -> 0.039285032 | J78: =J77+27.5 -> 297.5 | K78: =F78-J78 -> -14.640129 | L78: =K78/4000 -> -0.0036600323 | O78: =J77-J78 -> -27.5 | P78: =F77-F78 -> -11.435284
C79: 1.8645833 | D79: 1.875 | E79: 440 | F79: 361.83007 | G79: =E79-F79 -> 78.169925 | H79: =G79/4000 -> 0.019542481 | J79: =J78+40 -> 337.5 | K79: =F79-J79 -> 24.330075 | L79: =K79/4000 -> 0.0060825187 | O79: =J78-J79 -> -40 | P79: =F78-F79 -> -78.970204
C80: 1.875 | D80: 1.8854167 | E80: 440 | F80: 419.32273 | G80: =E80-F80 -> 20.677274 | H80: =G80/4000 -> 0.0051693186 | J80: =J79+40 -> 377.5 | K80: =F80-J80 -> 41.822726 | L80: =K80/4000 -> 0.010455681 | O80: =J79-J80 -> -40 | P80: =F79-F80 -> -57.492651
C81: 1.8854167 | D81: 1.8958333 | E81: 440 | F81: 422.89773 | G81: =E81-F81 -> 17.102271 | H81: =G81/4000 -> 0.0042755677 | J81: =J80+40 -> 417.5 | K81: =F81-J81 -> 5.3977294 | L81: =K81/4000 -> 0.0013494323 | O81: =J80-J81 -> -40 | P81: =F80-F81 -> -3.5750036
I82: =SUM(H72:H81) -> 0.258252 | M82: =SUM(L72:L81) -> -0.014127527 | O82: =J81-J82 -> 417.5 | P82: =F81-F82 -> 422.89773
B83: 45932 | C83: 1.9270833 | D83: 1.9375 | E83: 410 | F83: 397.69859 | G83: =E83-F83 -> 12.301408 | H83: =G83/4000 -> 0.003075352 | J83: =E83-27.5 -> 382.5 | K83: =F83-J83 -> 15.198592
C84: 1.9375 | D84: 1.9479167 | E84: 410 | F84: 301.74443 | G84: =E84-F84 -> 108.25557 | H84: =G84/4000 -> 0.027063893 | J84: =J83-40 -> 342.5 | K84: =F84-J84 -> -40.755574 | L84: =K84/4000 -> -0.010188893
C85: 1.9479167 | D85: 1.9583333 | E85: 410 | F85: 273.53086 | G85: =E85-F85 -> 136.46914 | H85: =G85/4000 -> 0.034117286 | J85: =J84-40 -> 302.5 | K85: =F85-J85 -> -28.969145 | L85: =K85/4000 -> -0.0072422862
C86: 1.9583333 | D86: 1.96875 | E86: 410 | F86: 269.19275 | G86: =E86-F86 -> 140.80725 | H86: =G86/4000 -> 0.035201813 | J86: 270 | K86: =F86-J86 -> -0.80725037 | L86: =K86/4000 -> -0.00020181259
C87: 1.96875 | D87: 1.9791667 | E87: 410 | F87: 269.35641 | G87: =E87-F87 -> 140.64359 | H87: =G87/4000 -> 0.035160896 | J87: 270 | K87: =F87-J87 -> -0.64358521 | L87: =K87/4000 -> -0.0001608963
...

Sheet Sheet1 (2)
G2: ABSTRACT of Backing down details of HNPCL for the month of sep 2025
G3: Date | H3: Backing down in MU | I3: Non compliance in MU | K3: 5 minutes average | L3: 10 minutes average | M3: 15 minutes average
B4: 1 | C4: 1.0104167 | G4: 45931 | H4: 0 | I4: 0 | K4: 5 | L4: 5 | M4: 5
B5: 1.0104167 | C5: 1.0208333 | G5: 45932 | H5: ='New method (2)'!I71+'New method (2)'!I82+'New method (2)'!I90 -> 3.108454 | I5: ='New method (2)'!M71+'New method (2)'!M82+'New method (2)'!M90 -> -0.025747371 | K5: 10 | L5: 10 | M5: 10
B6: 1.0208333 | C6: 1.03125 | G6: 45933 | H6: ='New method (2)'!I115+'New method (2)'!I155 -> 1.8706778 | I6: ='New method (2)'!M115+'New method (2)'!M155 -> -0.02411254 | K6: 15 | L6: 15 | M6: 15
B7: 1.03125 | C7: 1.0416667 | G7: 45934 | H7: ='New method (2)'!I162 -> 0.11346413 | I7: ='New method (2)'!M162 -> 0.0098170177 | K7: 20 | L7: 20 | M7: 20
B8: 1.0416667 | C8: 1.0520833 | G8: 45935 | H8: ='New method (2)'!I170+'New method (2)'!I185+'New method (2)'!I195+'New method (2)'!I208+'New method (2)'!I219 -> 1.3685835 | I8: ='New method (2)'!M170+'New method (2)'!M185+'New method (2)'!M195+'New method (2)'!M208+'New method (2)'!M219 -> -0.073513609 | K8: 25 | L8: 25 | M8: 25
B9: 1.0520833 | C9: 1.0625 | G9: 45936 | H9: ='New method (2)'!I248+'New method (2)'!I271 -> 2.169817 | I9: ='New method (2)'!M248+'New method (2)'!M271 -> -0.019150387 | J9: for 1 unit | K9: =AVERAGE(K4:K8) -> 15 | L9: 30 | M9: 30
B10: 1.0625 | C10: 1.0729167 | G10: 45937 | H10: ='New method (2)'!I286+'New method (2)'!I309+'New method (2)'!I321 -> 1.8456463 | I10: ='New method (2)'!M309+'New method (2)'!M321 -> -0.012915733 | J10: for 2 units | K10: 30 | L10: 35 | M10: 35
B11: 1.0729167 | C11: 1.0833333 | G11: 45938 | H11: ='New method (2)'!I337 -> 0.58081817 | I11: ='New method (2)'!M337 -> -0.014799122 | L11: 40 | M11: 40
B12: 1.0833333 | C12: 1.09375 | G12: 45939 | H12: ='New method (2)'!I367 -> 1.2036597 | I12: ='New method (2)'!M367 -> -0.0015654188 | L12: 45 | M12: 45
B13: 1.09375 | C13: 1.1041667 | G13: 45940 | H13: ='New method (2)'!I395+'New method (2)'!I405 -> 1.3744992 | I13: ='New method (2)'!M395+'New method (2)'!M405 -> -0.036299048 | L13: 50 | M13: 50
B14: 1.1041667 | C14: 1.1145833 | G14: 45941 | H14: ='New method (2)'!I446 -> 1.837656 | I14: ='New method (2)'!M446 -> 0.059404907 | K14: for 1 unit | L14: =AVERAGE(L4:L13) -> 27.5 | M14: 55
B15: 1.1145833 | C15: 1.125 | G15: 45942 | H15: ='New method (2)'!I491+'New method (2)'!I509 -> 2.5252208 | I15: ='New method (2)'!M491+'New method (2)'!M509 -> 0.051989309 | K15: for 2 units | L15: 55 | M15: 60
B16: 1.125 | C16: 1.1354167 | G16: 45943 | H16: ='New method (2)'!I554+'New method (2)'!I567 -> 2.4795024 | I16: ='New method (2)'!M554+'New method (2)'!M567 -> -0.035989735 | M16: 65
B17: 1.1354167 | C17: 1.1458333 | G17: 45944 | H17: ='New method (2)'!I595+'New method (2)'!I604 -> 1.4355549 | I17: ='New method (2)'!M595+'New method (2)'!M604 -> 0.34785932 | M17: 70
B18: 1.1458333 | C18: 1.15625 | G18: 45945 | H18: ='New method (2)'!I616+'New method (2)'!I661 -> 2.1464973 | I18: ='New method (2)'!M616+'New method (2)'!M661 -> -0.093655839 | M18: 75
B19: 1.15625 | C19: 1.1666667 | G19: 45946 | H19: ='New method (2)'!I685+'New method (2)'!I702 -> 1.2534659 | I19: ='New method (2)'!M685+'New method (2)'!M702 -> -0.020896189 | L19: for 1 unit | M19: =AVERAGE(M4:M18) -> 40
B20: 1.1666667 | C20: 1.1770833 | G20: 45947 | H20: ='New method (2)'!I747 -> 1.7293287 | I20: ='New method (2)'!M747 -> -0.019450253 | L20: for 2 units | M20: 80
B21: 1.1770833 | C21: 1.1875 | G21: 45948 | H21: 0 | I21: 0
B22: 1.1875 | C22: 1.1979167 | G22: 45949 | H22: ='New method (2)'!I778+'New method (2)'!I788 -> 1.3776654 | I22: ='New method (2)'!M778+'New method (2)'!M788 -> -0.0044517542
B23: 1.1979167 | C23: 1.2083333 | G23: 45950 | H23: ='New method (2)'!I829+'New method (2)'!I843 -> 2.1944911 | I23: ='New method (2)'!M829+'New method (2)'!M843 -> 0.020278343
B24: 1.2083333 | C24: 1.21875 | G24: 45951 | H24: ='New method (2)'!I880 -> 1.5476266 | I24: ='New method (2)'!M880 -> -0.047650578
B25: 1.21875 | C25: 1.2291667 | G25: 45952 | H25: ='New method (2)'!I923+'New method (2)'!I930 -> 1.7643024 | I25: ='New method (2)'!M923+'New method (2)'!M930 -> -0.048160294
B26: 1.2291667 | C26: 1.2395833 | G26: 45953 | H26: ='New method (2)'!I942+'New method (2)'!I975 -> 1.5852122 | I26: ='New method (2)'!M942+'New method (2)'!M975 -> -0.0022385064
B27: 1.2395833 | C27: 1.25 | G27: 45954 | H27: ='New method (2)'!I1000 -> 1.028058 | I27: ='New method (2)'!M1000 -> 0.0066698733
B28: 1.25 | C28: 1.2604167 | G28: 45955 | H28: ='New method (2)'!I1034 -> 1.4052436 | I28: ='New method (2)'!M1034 -> 0.040142977
B29: 1.2604167 | C29: 1.2708333 | G29: 45956 | H29: ='New method (2)'!I1077 -> 1.6681318 | I29: ='New method (2)'!M1077 -> 0.023993334
B30: 1.2708333 | C30: 1.28125 | G30: 45957 | H30: ='New method (2)'!I1116+'New method (2)'!I1120 -> 0.39288382 | I30: ='New method (2)'!M1116+'New method (2)'!M1120 -> 0.021723834
B31: 1.28125 | C31: 1.2916667 | G31: 45958 | H31: ='New method (2)'!I1156+'New method (2)'!I1180 -> 0.53928678 | I31: ='New method (2)'!M1156+'New method (2)'!M1180 -> 0.0186095
B32: 1.2916667 | C32: 1.3020833 | G32: 45959 | H32: 0 | I32: 0
B33: 1.3020833 | C33: 1.3125 | G33: 45960 | H33: 0 | I33: 0
B34: 1.3125 | C34: 1.3229167 | G34: 45961 | H34: 0 | I34: 0
B35: 1.3229167 | C35: 1.3333333 | G35: Total | H35: =SUM(H4:H34) -> 40.545748 | I35: =SUM(I4:I34) -> 0.11989204
B36: 1.3333333 | C36: 1.34375
B37: 1.34375 | C37: 1.3541667
B38: 1.3541667 | C38: 1.3645833
B39: 1.3645833 | C39: 1.375
B40: 1.375 | C40: 1.3854167
B41: 1.3854167 | C41: 1.3958333
...

Sheet Sheet1
R5: 1 | S5: 0 | U5: 0
R6: 2 | S6: 3.108454 | U6: 3.108454 | V6: =U6-S6 -> 0
R7: 3 | S7: 1.8706778 | U7: 1.8706778 | V7: =U7-S7 -> 0
R8: 4 | S8: 0.11346413 | U8: 0.11346413 | V8: =U8-S8 -> 0
R9: 5 | S9: 1.3685835 | U9: 1.3685835 | V9: =U9-S9 -> 0
R10: 6 | S10: 2.169817 | U10: 2.169817 | V10: =U10-S10 -> 0
R11: 7 | S11: 1.8456463 | U11: 1.843419 | V11: =U11-S11 -> -0.0022272847
R12: 8 | S12: 0.58081817 | U12: 0.58627952 | V12: =U12-S12 -> 0.0054613493
R13: 9 | S13: 1.2036597 | U13: 1.2036597 | V13: =U13-S13 -> 0
R14: 10 | S14: 1.3744992 | U14: 1.3744992 | V14: =U14-S14 -> 0
R15: 11 | S15: 1.837656 | U15: 1.837656 | V15: =U15-S15 -> 0
R16: 12 | S16: 2.5252208 | U16: 2.5261972 | V16: =U16-S16 -> 0.00097642398
R17: 13 | S17: 2.4795024 | U17: 2.4795024 | V17: =U17-S17 -> 0
... R35: 31 | S35: 0 | U35: 0 | V35: =U35-S35 -> 0
V36: =SUM(V6:V35) -> 0.0060137024

Sheet Sheet3
I4: hinduja
J5: from | L5: to
I6: 45932 | J6: 0.10416667 | L6: 0.75
I7: 45932 | J7: 0.79861111 | L7: 0.85763889
I8: 45932 | J8: 0.93055556 | L8: 1
I9: 45933 | J9: 0 | L9: 0.17361111
I10: 45933 | J10: 0.23958333 | L10: 0.60416667
I11: 45934 | J11: 0.45833333 | L11: 0.49305556
I12: 45935 | J12: 0.33680556 | L12: 0.375
I13: 45935 | J13: 0.43402778 | L13: 0.52083333
I14: 45935 | J14: 0.57638889 | L14: 0.61805556
I15: 45935 | J15: 0.79861111 | L15: 0.86805556
I16: 45935 | J16: 0.91666667 | L16: 1
I17: 45936 | J17: 0 | L17: 0.25
... I51: 45958 | J51: 0.36805556 | L51: 0.57708333
